Workbook

Sheet Summary
A2: Investments | B2: Actual Investment ('000 G$) | C2: ENPV ('000 g$) | D2: EIRR (%) | E2: FNPV ('000 G$) | F2: FIRR (%) | G2: BM implementation
A3: A. Total investment in various activity (Additional financing)
A4: Cassavs | B4: =('Cool Reflective Roof Coating'!F12+'Cool Reflective Roof Coating'!F21)/1000 -> 5650 | C4: ='Cool Reflective Roof Coating'!G68/1000 -> 4966.6541 | D4: ='Cool Reflective Roof Coating'!G67 -> 0.25239453 | E4: ='Cool Reflective Roof Coating'!G31/1000 -> 5500.63 | F4: ='Cool Reflective Roof Coating'!G30 -> 0.28445843 | G4: =L7/(B4*100) -> 813.80531 | K4: Total additional financing= US$ 11million | L4: 9000000 | O4: Total financing= US$ 10million | P4: 9000000
A5: Spice processing | B5: =('Ceiling Installation + Roof Ins'!F12+'Ceiling Installation + Roof Ins'!F23)/1000 -> 8908 | C5: ='Ceiling Installation + Roof Ins'!G72/1000 -> 3000.1885 | D5: ='Cross Ventilation Improvements'!G69 -> 0.16945185 | E5: ='Ceiling Installation + Roof Ins'!G33/1000 -> 5248.7725 | F5: ='Ceiling Installation + Roof Ins'!G32 -> 0.32578271 | G5: =L8/(B5*100) -> 387.12393 | K5: Total(G$) | L5: ='Additional financing total'!V13 -> 2299000000 | O5: Total(G$) | P5: =P4*208 -> 1872000000
A6: poultry | B6: =('Cross Ventilation Improvements'!H12+'Cross Ventilation Improvements'!H20)/1000 -> 5650.71 | C6: ='Cross Ventilation Improvements'!G70/1000 -> 24528.25 | D6: ='Ceiling Installation + Roof Ins'!G71 -> 0.27935087 | E6: ='Cross Ventilation Improvements'!G70/1000 -> 24528.25 | F6: ='Cross Ventilation Improvements'!G29 -> 0.16676295 | G6: =L9/(B6*100) -> 406.85153 | K6: Additional financing | L6: budget(G$) | M6: Budget(%) | O6: Additional financing | P6: budget(G$) | Q6: Budget(%)
A7: cattle | B7: =('External Shading (Awnings, Over'!G13+'External Shading (Awnings, Over'!G23)/1000 -> 360 | C7: ='External Shading (Awnings, Over'!G65/1000 -> 586.74751 | D7: ='External Shading (Awnings, Over'!G64 -> 0.33955408 | E7: ='External Shading (Awnings, Over'!G32/1000 -> 905.00181 | F7: ='External Shading (Awnings, Over'!G31 -> 0.32300371 | G7: =L10/(B7*100) -> 6386.1111 | K7: Cassava | L7: =L5*0.2 -> 459800000 | M7: 0.2 | O7: peanut TF | P7: =P5*0.2 -> 374400000 | Q7: 0.2
A8: Cassava processing | B8: =('Efficient Fans (DC or Energy-Ef'!F13+'Efficient Fans (DC or Energy-Ef'!F23)/1000 -> 7043.9 | C8: ='Efficient Fans (DC or Energy-Ef'!G67/1000 -> 2348.9085 | D8: ='Efficient Fans (DC or Energy-Ef'!G66 -> 0.20146258 | E8: =-('Efficient Fans (DC or Energy-Ef'!G33)/1000 -> 5643.3445 | F8: ='Efficient Fans (DC or Energy-Ef'!G32 -> 0.21726914 | G8: =L11/(B8*100) -> 326.38169 | K8: Spice processing | L8: =L5*0.15 -> 344850000 | M8: 0.15 | O8: cassava TF | P8: =P5*0.2 -> 374400000 | Q8: 0.2
A9: Honey | B9: =(Honey!F12+Honey!H27)/1000 -> 718.66667 | C9: =Honey!G71/1000 -> 197.7827 | D9: =Honey!G70 -> 0.36311265 | E9: =Honey!G32/1000 -> 215.44541 | F9: =Honey!G31 -> 0.35865753 | G9: =L12/(B9*100) -> 3198.9796 | K9: poutry | L9: =L5*0.1 -> 229900000 | M9: 0.1 | O9: poutry breedingTF | P9: =P5*0.15 -> 280800000 | Q9: 0.15
A10: School kitchen garden | B10: =('School kitchen gardening'!G10+'School kitchen gardening'!G20)/1000 -> 504.9 | C10: ='School kitchen gardening'!G64/1000 -> 146.54142 | D10: ='School kitchen gardening'!G63 -> 0.16984724 | E10: ='School kitchen gardening'!G31/1000 -> 149.87188 | F10: ='School kitchen gardening'!G30 -> 0.18940992 | G10: =L13/(B10*100) -> 4553.3769 | K10: Cattle | L10: =L5*0.1 -> 229900000 | M10: 0.25 | O10: Cattle breeding TF | P10: =P5*0.1 -> 187200000 | Q10: 0.25
A11: Total 1 unit investment cost(additional Financing) | B11: =SUM(B4:B10)*1000 -> 28836177 | C11: =(SUM(C4:C10)/SUM(B4:B10))*B11 -> 35775073 | D11: =(D4*B4+D5*B5+D6*B6+D7*B7+D9*B9+D10*B10)/(SUM(B4:B10)) -> 0.1728034 | E11: =(SUM(E4:E10)/SUM(B4:B10))*B11 -> 42191317 | F11: =(F4*B4+F5*B5+F6*B6+F7*B7+F9*B9+F10*B10)/SUM(B4:B10) -> 0.20534141 | K11: Cassava processing | L11: =L5*0.1 -> 229900000 | M11: 0.1 | O11: Cassava processing TF | P11: =P5*0.1 -> 187200000 | Q11: 0.1
A12: B. Total investment in various activity (Total financing) | K12: Honey | L12: =L5*0.1 -> 229900000 | M12: 0.1 | O12: guest house TF | P12: =P5*0.1 -> 187200000 | Q12: 0.1
A13: peanut TF | B13: =('Peanut TF'!F11+'Peanut TF'!F21)/1000 -> 671.5 | C13: ='Peanut TF'!G32/1000 -> 545.16928 | D13: ='Peanut TF'!G65 -> 0.27723132 | E13: ='Peanut TF'!G66/1000 -> 587.57698 | F13: ='Peanut TF'!G31 -> 0.29104771 | G13: =P7/(B13*100) -> 5575.5771 | K13: School kitchen garden | L13: =L5*0.1 -> 229900000 | M13: 0.1
A14: Cassava TF | B14: =('Cassava TF'!F12+'Cassava TF'!F21)/1000 -> 4650 | C14: ='Cassava TF'!G31/1000 -> 3755.6957 | D14: ='Cassava TF'!G30 -> 0.21348721 | E14: ='Cassava TF'!G68/1000 -> 2705.9999 | F14: ='Cassava TF'!G30 -> 0.21348721 | G14: =P8/(E14*100) -> 1383.5921
A15: Cassava processing TF | B15: =('Cassava processing TF'!F13+'Cassava processing TF'!F23)/1000 -> 6470.81 | C15: ='Cassava processing TF'!G33/1000 -> 2374.0297 | D15: ='Cassava processing TF'!G66 -> 0.23377797 | E15: ='Cassava processing TF'!G67/1000 -> 7829.0322 | F15: ='Efficient Fans (DC or Energy-Ef'!G32 -> 0.21726914 | G15: =P11/(B15*100) -> 289.29918
A16: cattle breeding TF | B16: =('cattle breeding TF'!F13+'cattle breeding TF'!G22)/1000 -> 3348 | C16: ='cattle breeding TF'!G65/1000 -> 3767.5349 | D16: ='cattle breeding TF'!G64 -> 0.19550723 | E16: ='cattle breeding TF'!G32/1000 -> 3594.7774 | F16: ='cattle breeding TF'!G31 -> 0.23765602 | G16: =P10/(B16*100) -> 559.13978
A17: poultry breeding TF | B17: =('Poutry breeding TF'!E11+'Poutry breeding TF'!F20)/1000 -> 5500.71 | C17: ='Poutry breeding TF'!G70/1000 -> 2990.5342 | D17: ='Poutry breeding TF'!G69 -> 0.16945185 | E17: ='Poutry breeding TF'!G30/1000 -> 2878.0265 | F17: ='Poutry breeding TF'!G29 -> 0.21018031 | G17: =P9/(B17*100) -> 510.47956
A18: guest house | B18: =-(GH!D7) -> 400000 | C18: =GH!D22/1000 -> 1918.5773 | D18: =GH!D23 -> 0.21393484 | E18: =-(GH!D27)/1000 -> -1234.7878 | F18: =GH!D28 -> 0.17820161 | G18: =P12/(B18) -> 468
A19: Total 1 unit investment cost(Total Financing) | B19: =SUM(B13:B18)*1000 -> 420641020 | C19: =(SUM(C13:C18)/SUM(B13:B18))*B19 -> 15351541 | D19: =(D13*B13+D14*B14+D15*B15+D16*B16+D17*B17+D18*B18)/(SUM(B13:B18)) -> 0.21360781 | E19: =(SUM(E13:E18)/SUM(B13:B18))*B19 -> 16360625 | F19: =(F13*B13+F14*B14+F15*B15+F16*B16+F17*B17+F18*B18)/SUM(B13:B18) -> 0.1802642
B21: =SUM(B4:B10) -> 28836.177
A23: =

Sheet prices and other data
D3: 2025 million usd
C4: Total export f.o.b | D4: 8280000000 | E4: 1989.77
C5: Total import c.i.f | D5: =4160*208 -> 865280 | E5: 3522.2
C6: Export duties | D6: =N11 -> ~US$10.09 billion
C7: Import duties | D7: =D5*0.2 -> 173056
C8: VAT on imports | D8: =D5*0.1 -> 86528
C9: Excise duties on imports | D9: =0.03*D5 -> 25958.4 | M9: Variable | N9: Recent Mozambique Value | O9: Notes / Suggested Use in EFA
M10: Total exports (f.o.b.) | N10: ~US$8.28 billion | O10: WITS/World Bank merchandise exports (World Integrated Trade Solution)
C11: Conversion factor | D11: 0.9 | M11: Total imports (c.i.f.) | N11: ~US$10.09 billion | O11: WITS/World Bank merchandise imports (World Integrated Trade Solution)
M12: Export duties | N12: Very limited / low | O12: Mozambique relies much more on import taxation than export duties (Trading Economics)
M13: Import duties | N13: Typically 0%–20% | O13: Depends on tariff classification (PwC Tax Summaries)
C14: VAT Tax rate (fixed for last 5 Years) | D14: 0.14 | M14: VAT on imports | N14: 16% VAT | O14: Standard VAT rate applied to imports and domestic goods
M15: Excise duties on imports | N15: Product specific | O15: Tobacco, alcohol, luxury items, vehicles, etc. (PwC Tax Summaries)
C16: Official Exchange Rate (2022) | D16: 64 | M16: Conversion factor | N16: 0.90–0.95 (typical WB assumption) | O16: Often used in EFA when estimating shadow pricing/tradable adjustments
M17: VAT tax rate | N17: 0.16 | O17: Fixed standard VAT rate in recent years
M18: Official exchange rate (2022) | N18: ~63–64 MZN per US$ | O18: Metical remained relatively stable since 2021 (IMF)
M19: Currency | N19: Mozambican Metical (MZN) | O19: Standard national currency
M20: Interest rate / discount rate for NPV | N20: 10%–12% commonly used | O20: WB economic analysis often uses 6–12%; financial analysis may use local borrowing costs
M21: Wage of labor – Family labor | N21: Shadow wage often below market wage | O21: Frequently adjusted downward in economic analysis
C22: BASIC DATA | M22: Wage of labor – Hired labor | N22: Market wage | O22: Use local construction/labor survey rates
C23: Currency | D23: MZN
C24: Exchange rate | D24: 1 | E24: USD = | F24: 64 | G24: MZN
C25: Interest rate (NPV) | D25: 0.14 | E25: 14%
C27: WAGE OF LABOR
C28: Tipo de mano de obra | E28: Wage MZN | G28: FC
E29: financial | F29: economic
C30: Family | D30: day | E30: 750 | F30: 750 | G30: 1
C31: Hired | D31: day | E31: 900 | F31: 900 | G31: 1

Sheet Cool   Reflective Roof Coating
B1: FINANCIAL
C2: Unit | D2: Quantity | E2: Price | F2: Amount | G2: Year
B3: REVENUE | G3: 1 | H3: =G3+1 -> 2 | I3: =H3+1 -> 3 | J3: =I3+1 -> 4 | K3: =J3+1 -> 5 | L3: =K3+1 -> 6 | M3: =L3+1 -> 7 | N3: =M3+1 -> 8 | O3: =N3+1 -> 9 | P3: =O3+1 -> 10 | Q3: 11 | R3: 12 | S3: 13 | T3: 14 | U3: 15
B4: Energy saved | C4: lbs | D4: 10000 | E4: 650 | F4: =D4*E4 -> 6500000 | G4: =F4*0.5 -> 3250000 | H4: =F4 -> 6500000 | I4: =F4 -> 6500000 | J4: =F4 -> 6500000 | K4: =J4 -> 6500000 | L4: =K4 -> 6500000 | M4: =L4 -> 6500000 | N4: =M4 -> 6500000 | O4: =N4 -> 6500000 | P4: =O4 -> 6500000 | Q4: =P4 -> 6500000 | R4: =Q4 -> 6500000 | ... U4: =T4 -> 6500000
B6: Sub-total Revenue | F6: =SUM(F4:F5) -> 6500000 | G6: =SUM(G4:G5) -> 3250000 | H6: =SUM(H4:H5) -> 6500000 | I6: =SUM(I4:I5) -> 6500000 | J6: =SUM(J4:J5) -> 6500000 | K6: =SUM(K4:K5) -> 6500000 | L6: =SUM(L4:L5) -> 6500000 | M6: =SUM(M4:M5) -> 6500000 | ... U6: =SUM(U4:U5) -> 6500000
B8: CAPEX
B9: Investment Costs
B10: Installment and other | C10: lumpsum | D10: 10 | E10: 100000 | F10: =D10*E10 -> 1000000 | G10: =D10*E10 -> 1000000 | H10: =G10 -> 1000000 | I10: 0 | J10: 0 | L10: =G10 -> 1000000 | O10: =L10 -> 1000000 | P10: =K10 -> 0 | T10: =O10 -> 1000000
B11: Other Fixed Cost | C11: lumpsum | D11: 1 | E11: 50000 | F11: =D11*E11 -> 50000 | G11: =D11*E11 -> 50000 | H11: 0 | I11: 0 | J11: 0 | K11: 0
B12: Sub-total Investment | F12: =SUM(F10:F11) -> 1050000 | G12: =SUM(G10:G11) -> 1050000 | H12: =SUM(H10:H11) -> 1000000 | I12: =SUM(I10:I11) -> 0 | J12: =SUM(J10:J11) -> 0 | K12: =SUM(K10:K11) -> 0 | M12: =SUM(M10:M11) -> 0 | N12: =SUM(N10:N11) -> 0 | P12: =SUM(P10:P11) -> 0 | R12: =SUM(R10:R11) -> 0 | S12: =SUM(S10:S11) -> 0 | T12: =SUM(T10:T11) -> 1000000 | U12: =SUM(U10:U11) -> 0
F13: =D13*E13 -> 0
B14: OPEX – Cool Reflective Roof | F14: =D14*E14 -> 0
B15: OPEX – Cool Reflective Roof | C15: MZK | E15: 1000000 | F15: =E15 -> 1000000 | G15: =F15 -> 1000000 | H15: =F15 -> 1000000 | I15: =H15 -> 1000000 | J15: =I15 -> 1000000 | K15: =J15 -> 1000000 | L15: =K15 -> 1000000 | M15: =L15 -> 1000000 | N15: =M15 -> 1000000 | O15: =N15 -> 1000000 | P15: =O15 -> 1000000 | ... U15: =T15 -> 1000000
B16: Wages and Labor | C16: MZK | D16: 2000 | E16: 900 | F16: =D16*E16 -> 1800000 | G16: =F16*0.75 -> 1350000 | H16: =F16 -> 1800000 | I16: =H16 -> 1800000 | J16: =I16 -> 1800000 | K16: =J16 -> 1800000 | L16: =K16 -> 1800000 | M16: =L16 -> 1800000 | N16: =M16 -> 1800000 | O16: =N16 -> 1800000 | P16: =O16 -> 1800000 | ... U16: =T16 -> 1800000
B17: Roof Maintenance | C17: MZK | D17: 12 | E17: 45000 | F17: =D17*E17 -> 540000 | G17: =F17 -> 540000 | H17: =D17*E17*1 -> 540000 | I17: =D17*E17*1 -> 540000 | J17: =D17*E17 -> 540000 | K17: =J17 -> 540000 | L17: =K17 -> 540000 | M17: =L17 -> 540000 | N17: =M17 -> 540000 | O17: =N17 -> 540000 | P17: =O17 -> 540000 | Q17: =P17 -> 540000 | R17: =Q17 -> 540000 | ... U17: =T17 -> 540000
B18: Reflective Coating Reapplication | C18: MZK | D18: 12 | E18: 55000 | F18: =D18*E18 -> 660000 | G18: =F18 -> 660000 | H18: =F18 -> 660000 | I18: =H18 -> 660000 | J18: =I18 -> 660000 | K18: =J18 -> 660000 | L18: =K18 -> 660000 | M18: =L18 -> 660000 | N18: =M18 -> 660000 | O18: =N18 -> 660000 | P18: =O18 -> 660000 | ... U18: =T18 -> 660000
B19: Cleaning and Repair | C19: MZK | D19: 100 | E19: 1000 | F19: =D19*E19 -> 100000 | G19: =F19 -> 100000 | H19: =G19 -> 100000 | I19: =H19 -> 100000 | J19: =I19 -> 100000 | K19: =J19 -> 100000 | L19: =K19 -> 100000 | M19: =L19 -> 100000 | N19: =M19 -> 100000 | ... U19: =T19 -> 100000
B20: Equipment and Material Replacement | C20: MZK | D20: 1 | E20: 500000 | F20: =D20*E20 -> 500000 | G20: =F20 -> 500000 | H20: =F20 -> 500000 | I20: =F20 -> 500000 | J20: =F20 -> 500000 | K20: =J20 -> 500000 | L20: =K20 -> 500000 | M20: =L20 -> 500000 | N20: =M20 -> 500000 | O20: =N20 -> 500000 | P20: =O20 -> 500000 | Q20: =P20 -> 500000 | R20: =Q20 -> 500000 | ... U20: =T20 -> 500000
B21: Sub-total for Operating costs | F21: =SUM(F15:F20) -> 4600000 | G21: =SUM(G15:G20) -> 4150000 | H21: =SUM(H15:H20) -> 4600000 | I21: =SUM(I15:I20) -> 4600000 | J21: =SUM(J15:J20) -> 4600000 | K21: =SUM(K15:K20) -> 4600000 | L21: =SUM(L15:L20) -> 4600000 | M21: =SUM(M15:M20) -> 4600000 | ... U21: =SUM(U15:U20) -> 4600000
B23: Fixed costs
B24: Depreciation | C24: MZK/annum | D24: 1 | E24: =E11/12 -> 4166.6667 | F24: =D24*E24 -> 4166.6667 | G24: =F24 -> 4166.6667 | H24: =D24*E24 -> 4166.6667 | I24: =H24 -> 4166.6667 | J24: =I24 -> 4166.6667 | K24: =J24 -> 4166.6667 | L24: =K24 -> 4166.6667 | M24: =L24 -> 4166.6667 | N24: =M24 -> 4166.6667 | O24: =N24 -> 4166.6667 | P24: =O24 -> 4166.6667 | ... U24: =T24 -> 4166.6667 | V24: =SUM(H24:U24) -> 58333.333
B25: Sub-total for Fixed costs | F25: =SUM(F24:F24) -> 4166.6667 | G25: =SUM(G24:G24) -> 4166.6667 | H25: =SUM(H24:H24) -> 4166.6667 | I25: =SUM(I24:I24) -> 4166.6667 | J25: =SUM(J24:J24) -> 4166.6667 | K25: =SUM(K24:K24) -> 4166.6667 | L25: =SUM(L24:L24) -> 4166.6667 | M25: =SUM(M24:M24) -> 4166.6667 | ... U25: =SUM(U24:U24) -> 4166.6667
B26: TOTAL COSTS | F26: =F12+F21+F25 -> 5654166.7 | G26: =G12+G21+G25 -> 5204166.7 | H26: =H12+H21+H25 -> 5604166.7 | I26: =I12+I21+I25 -> 4604166.7 | J26: =J12+J21+J25 -> 4604166.7 | K26: =K12+K21+K25 -> 4604166.7 | L26: =L12+L21+L25 -> 4604166.7 | M26: =M12+M21+M25 -> 4604166.7 | ... U26: =U12+U21+U25 -> 4604166.7
B28: GROSS MARGIN | C28: MZK/annum | G28: =G6-G12-G21 -> -1950000 | H28: =H6-H12-H21 -> 900000 | I28: =I6-I12-I21 -> 1900000 | J28: =J6-J12-J21 -> 1900000 | K28: =K6-K12-K21 -> 1900000 | L28: =L6-L12-L21 -> 1900000 | M28: =M6-M12-M21 -> 1900000 | N28: =N6-N12-N21 -> 1900000 | ... U28: =U6-U12-U21 -> 1900000
B29: NET MARGIN BEFORE PROFIT TAX | C29: MZK/annum | G29: =G28-G25 -> -1954166.7 | H29: =-(H28-H25) -> -895833.33 | I29: =-(I28-I25) -> -1895833.3 | J29: =J28-J25 -> 1895833.3 | K29: =K28-K25 -> 1895833.3 | L29: =L28-L25 -> 1895833.3 | M29: =M28-M25 -> 1895833.3 | N29: =N28-N25 -> 1895833.3 | O29: =O28-O25 -> 1895833.3 | P29: =P28-P25 -> 1895833.3 | Q29: =Q28-Q25 -> 1895833.3 | ... U29: =U28-U25 -> 1895833.3
B30: FIRR | G30: =IRR(G29:U29) -> 0.28445843
B31: FNPV | G31: =NPV(0.1,G29:U29) -> 5500630
B39: ECONOMIC
C40: Unit | D40: Quantity | E40: Price | F40: Amount | G40: Year
B41: REVENUE | G41: 1 | H41: =G41+1 -> 2 | I41: =H41+1 -> 3 | J41: =I41+1 -> 4 | K41: =J41+1 -> 5 | L41: =K41+1 -> 6 | M41: =L41+1 -> 7 | N41: =M41+1 -> 8 | O41: =N41+1 -> 9 | P41: =O41+1 -> 10 | Q41: 11 | R41: 12 | S41: 13 | T41: 14 | U41: 15
B42: =B4 -> Energy saved | C42: KWH/h | D42: =D4 -> 10000 | E42: =E4*0.92 -> 598 | F42: =D42*E42 -> 5980000 | G42: =F42*0.5 -> 2990000 | H42: =F42 -> 5980000 | I42: =F42 -> 5980000 | J42: =F42 -> 5980000 | K42: =J42 -> 5980000 | L42: =K42 -> 5980000 | M42: =L42 -> 5980000 | N42: =M42 -> 5980000 | O42: =N42 -> 5980000 | P42: =O42 -> 5980000 | Q42: =P42 -> 5980000 | R42: =Q42 -> 5980000 | ... U42: =T42 -> 5980000
B43: Sub-total Revenue | D43: =D6 -> 0 | E43: =E6*0.9 -> 0 | F43: =SUM(F42:F42) -> 5980000 | G43: =SUM(G42:G42) -> 2990000 | H43: =SUM(H42:H42) -> 5980000 | I43: =SUM(I42:I42) -> 5980000 | J43: =SUM(J42:J42) -> 5980000 | K43: =SUM(K42:K42) -> 5980000 | L43: =SUM(L42:L42) -> 5980000 | M43: =SUM(M42:M42) -> 5980000 | ... U43: =SUM(U42:U42) -> 5980000
D44: =D7 -> 0 | E44: =E7*0.9 -> 0
B45: COSTS | D45: =D8 -> 0 | E45: =E8*0.9 -> 0
B46: Investment Costs | D46: =D9 -> 0 | E46: =E9*0.9 -> 0
B47: installment cost | C47: lumpsum | D47: =D10 -> 10 | E47: =E10*0.9 -> 90000 | F47: =D47*E47 -> 900000 | G47: =D47*E47 -> 900000 | H47: 0 | I47: 0 | J47: 0 | P47: =K47 -> 0
B48: Other Fixed Cost | C48: lumpsum | D48: =D11 -> 1 | E48: =E11*0.9 -> 45000 | F48: =D48*E48 -> 45000 | G48: =D48*E48 -> 45000 | H48: 0 | I48: 0 | J48: 0 | K48: 0
B49: Sub-total Investment | D49: =D12 -> 0 | E49: =E12*0.9 -> 0 | F49: =SUM(F47:F48) -> 945000 | G49: =SUM(G47:G48) -> 945000 | H49: =SUM(H47:H48) -> 0 | I49: =SUM(I47:I48) -> 0 | J49: =SUM(J47:J48) -> 0 | K49: =SUM(K47:K48) -> 0 | L49: =SUM(L47:L48) -> 0 | M49: =SUM(M47:M48) -> 0 | ... U49: =SUM(U47:U48) -> 0
D50: =D13 -> 0 | E50: =E13*0.9 -> 0 | F50: =D50*E50 -> 0
B51: Operating costs | D51: =D14 -> 0 | E51: =E14*0.9 -> 0 | F51: =D51*E51 -> 0
...

Sheet Ceiling Installation + Roof Ins
B1: FINANCIAL
C2: Unit | D2: Quantity | E2: Price | F2: Amount | G2: Year
B3: REVENUE | G3: 1 | H3: =G3+1 -> 2 | I3: =H3+1 -> 3 | J3: =I3+1 -> 4 | K3: =J3+1 -> 5 | L3: =K3+1 -> 6 | M3: =L3+1 -> 7 | N3: =M3+1 -> 8 | O3: =N3+1 -> 9 | P3: =O3+1 -> 10 | Q3: 11 | R3: 12 | S3: 13 | T3: 14 | U3: 15
B4: Enegy saved | C4: lumpsum | F4: 4400000 | H4: =F4 -> 4400000 | I4: =F4 -> 4400000 | J4: =F4 -> 4400000 | K4: =J4 -> 4400000 | L4: =K4 -> 4400000 | M4: =L4 -> 4400000 | N4: =M4 -> 4400000 | O4: =N4 -> 4400000 | P4: =O4 -> 4400000 | Q4: =P4 -> 4400000 | R4: =Q4 -> 4400000 | ... U4: =T4 -> 4400000
B5: Productivity cost | C5: lumpsum | F5: 4600000 | H5: =F5 -> 4600000 | I5: =H5 -> 4600000 | J5: =H5 -> 4600000 | K5: =J5 -> 4600000 | L5: =K5 -> 4600000 | M5: =L5 -> 4600000 | N5: =M5 -> 4600000 | O5: =N5 -> 4600000 | P5: =O5 -> 4600000 | Q5: =P5 -> 4600000 | R5: =Q5 -> 4600000 | ... U5: =T5 -> 4600000
B6: Sub-total Revenue | F6: =SUM(F4:F5) -> 9000000 | G6: =SUM(G4:G5) -> 0 | H6: =SUM(H4:H5) -> 9000000 | I6: =SUM(I4:I5) -> 9000000 | J6: =SUM(J4:J5) -> 9000000 | K6: =SUM(K4:K5) -> 9000000 | L6: =SUM(L4:L5) -> 9000000 | M6: =SUM(M4:M5) -> 9000000 | ... U6: =SUM(U4:U5) -> 9000000
B8: COSTS
B9: Investment Costs
B10: Fixed Capital | C10: lumpsum | D10: 1 | E10: 1000000 | F10: =D10*E10 -> 1000000 | G10: =D10*E10 -> 1000000 | H10: 0 | I10: 0 | J10: 0 | P10: =K10 -> 0
B11: Cash in hand | C11: lumpsum | D11: 1 | E11: 300000 | F11: =D11*E11 -> 300000 | G11: =D11*E11 -> 300000 | H11: 0 | I11: 0 | J11: 0 | K11: 0
B12: Sub-total Investment | F12: =SUM(F10:F11) -> 1300000 | G12: =SUM(G10:G11) -> 1300000 | H12: =SUM(H10:H11) -> 0 | I12: =SUM(I10:I11) -> 0 | J12: =SUM(J10:J11) -> 0 | K12: =SUM(K10:K11) -> 0 | L12: =SUM(L10:L11) -> 0 | M12: =SUM(M10:M11) -> 0 | ... U12: =SUM(U10:U11) -> 0
F13: =D13*E13 -> 0
B14: Operating costs | F14: =D14*E14 -> 0
B15: Wages and Labor | C15: MZK | F15: =F4*0.8 -> 3520000 | G15: =F15*0.5 -> 1760000 | H15: =F15 -> 3520000 | I15: =H15 -> 3520000 | J15: =I15 -> 3520000 | K15: =J15 -> 3520000 | L15: =K15 -> 3520000 | M15: =L15 -> 3520000 | N15: =M15 -> 3520000 | O15: =N15 -> 3520000 | P15: =O15 -> 3520000 | ... U15: =T15 -> 3520000
B16: Ceiling Maintenance | C16: MZK | F16: 3000000 | H16: =F16 -> 3000000 | I16: =H16 -> 3000000 | J16: =I16 -> 3000000 | K16: =J16 -> 3000000 | L16: =K16 -> 3000000 | M16: =L16 -> 3000000 | N16: =M16 -> 3000000 | O16: =N16 -> 3000000 | P16: =O16 -> 3000000 | ... U16: =T16 -> 3000000
B17: Insulation Repair | C17: MZK | D17: 200 | E17: 4500 | F17: =D17*E17 -> 900000 | G17: =F17*0.75 -> 675000 | H17: =F17 -> 900000 | I17: =H17 -> 900000 | J17: =I17 -> 900000 | K17: =J17 -> 900000 | L17: =K17 -> 900000 | M17: =L17 -> 900000 | N17: =M17 -> 900000 | O17: =N17 -> 900000 | P17: =O17 -> 900000 | ... U17: =T17 -> 900000
B18: Cleaning and Minor Repair | C18: MZK | F18: 100000 | G18: =F18 -> 100000 | H18: =G18 -> 100000 | I18: =H18 -> 100000 | J18: =I18 -> 100000 | K18: =J18 -> 100000 | L18: =K18 -> 100000 | M18: =L18 -> 100000 | N18: =M18 -> 100000 | ... U18: =T18 -> 100000
B20: other | C20: MZK | F20: =F4*0.01 -> 44000 | G20: =F20 -> 44000 | H20: =F20 -> 44000 | I20: =H20 -> 44000 | J20: =I20 -> 44000 | K20: =J20 -> 44000 | L20: =K20 -> 44000 | M20: =L20 -> 44000 | N20: =M20 -> 44000 | O20: =N20 -> 44000 | P20: =O20 -> 44000 | ... U20: =T20 -> 44000
B21: Material Replacement | C21: MZK | F21: =F4*0.01 -> 44000 | G21: =F21 -> 44000 | H21: =G21 -> 44000 | I21: =H21 -> 44000 | J21: =I21 -> 44000 | K21: =J21 -> 44000 | L21: =K21 -> 44000 | M21: =L21 -> 44000 | N21: =M21 -> 44000 | ... U21: =T21 -> 44000
B23: Sub-total for Operating costs | F23: =SUM(F15:F22) -> 7608000 | G23: =SUM(G15:G22) -> 2623000 | H23: =SUM(H15:H22) -> 7608000 | I23: =SUM(I15:I22) -> 7608000 | J23: =SUM(J15:J22) -> 7608000 | K23: =SUM(K15:K22) -> 7608000 | L23: =SUM(L15:L22) -> 7608000 | M23: =SUM(M15:M22) -> 7608000 | ... U23: =SUM(U15:U22) -> 7608000
B25: Fixed costs
B26: Depreciation | C26: MZK/annum | D26: 1 | E26: =E10/15 -> 66666.667 | F26: =D26*E26 -> 66666.667 | G26: =F26 -> 66666.667 | H26: =D26*E26 -> 66666.667 | I26: =H26 -> 66666.667 | J26: =I26 -> 66666.667 | K26: =J26 -> 66666.667 | L26: =K26 -> 66666.667 | M26: =L26 -> 66666.667 | N26: =M26 -> 66666.667 | O26: =N26 -> 66666.667 | P26: =O26 -> 66666.667 | ... U26: =T26 -> 66666.667 | V26: =SUM(H26:U26) -> 933333.33
B27: Sub-total for Fixed costs | F27: =SUM(F26:F26) -> 66666.667 | G27: =SUM(G26:G26) -> 66666.667 | H27: =SUM(H26:H26) -> 66666.667 | I27: =SUM(I26:I26) -> 66666.667 | J27: =SUM(J26:J26) -> 66666.667 | K27: =SUM(K26:K26) -> 66666.667 | L27: =SUM(L26:L26) -> 66666.667 | M27: =SUM(M26:M26) -> 66666.667 | ... U27: =SUM(U26:U26) -> 66666.667
B28: TOTAL COSTS | F28: =F12+F23+F27 -> 8974666.7 | G28: =G12+G23+G27 -> 3989666.7 | H28: =H12+H23+H27 -> 7674666.7 | I28: =I12+I23+I27 -> 7674666.7 | J28: =J12+J23+J27 -> 7674666.7 | K28: =K12+K23+K27 -> 7674666.7 | L28: =L12+L23+L27 -> 7674666.7 | M28: =M12+M23+M27 -> 7674666.7 | ... U28: =U12+U23+U27 -> 7674666.7
B30: GROSS MARGIN | C30: MZK/annum | G30: =G6-G12-G23 -> -3923000 | H30: =H6-H12-H23 -> 1392000 | I30: =I6-I12-I23 -> 1392000 | J30: =J6-J12-J23 -> 1392000 | K30: =K6-K12-K23 -> 1392000 | L30: =L6-L12-L23 -> 1392000 | M30: =M6-M12-M23 -> 1392000 | N30: =N6-N12-N23 -> 1392000 | ... U30: =U6-U12-U23 -> 1392000
B31: NET MARGIN BEFORE PROFIT TAX | C31: MZK/annum | G31: =G30-G27 -> -3989666.7 | H31: =H30-H27 -> 1325333.3 | I31: =I30-I27 -> 1325333.3 | J31: =J30-J27 -> 1325333.3 | K31: =K30-K27 -> 1325333.3 | L31: =L30-L27 -> 1325333.3 | M31: =M30-M27 -> 1325333.3 | N31: =N30-N27 -> 1325333.3 | ... U31: =U30-U27 -> 1325333.3
B32: FIRR | G32: =IRR(G31:U31) -> 0.32578271
B33: FNPV | G33: =NPV(0.1,G31:U31) -> 5248772.5
B41: ECONOMIC
C42: Unit | D42: Quantity | E42: Price | F42: Amount | G42: Year
B43: REVENUE | G43: 1 | H43: =G43+1 -> 2 | I43: =H43+1 -> 3 | J43: =I43+1 -> 4 | K43: =J43+1 -> 5 | L43: =K43+1 -> 6 | M43: =L43+1 -> 7 | N43: =M43+1 -> 8 | O43: =N43+1 -> 9 | P43: =O43+1 -> 10 | Q43: 11 | R43: 12 | S43: 13 | T43: 14 | U43: 15
B44: Enegy saved | C44: lumpsum | F44: =F4*0.9 -> 3960000 | G44: =F44*0.5 -> 1980000 | H44: =F44 -> 3960000 | I44: =F44 -> 3960000 | J44: =F44 -> 3960000 | K44: =J44 -> 3960000 | L44: =K44 -> 3960000 | M44: =L44 -> 3960000 | N44: =M44 -> 3960000 | O44: =N44 -> 3960000 | P44: =O44 -> 3960000 | Q44: =P44 -> 3960000 | R44: =Q44 -> 3960000 | ... U44: =T44 -> 3960000
B45: Productivity cost | C45: lumpsum | F45: =F5*0.9 -> 4140000 | H45: =F45 -> 4140000 | I45: =H45 -> 4140000 | J45: =I45 -> 4140000 | K45: =J45 -> 4140000 | L45: =K45 -> 4140000 | M45: =L45 -> 4140000 | N45: =M45 -> 4140000 | O45: =N45 -> 4140000 | P45: =O45 -> 4140000 | ... U45: =T45 -> 4140000
B47: Sub-total Revenue | D47: =D6 -> 0 | E47: =E6*0.9 -> 0 | F47: =SUM(F44:F46) -> 8100000 | G47: =SUM(G44:G46) -> 1980000 | H47: =SUM(H44:H46) -> 8100000 | I47: =SUM(I44:I46) -> 8100000 | J47: =SUM(J44:J46) -> 8100000 | K47: =SUM(K44:K46) -> 8100000 | L47: =SUM(L44:L46) -> 8100000 | M47: =SUM(M44:M46) -> 8100000 | ... U47: =SUM(U44:U46) -> 8100000
D48: =D7 -> 0 | E48: =E7*0.9 -> 0
B49: CAPEX | D49: =D8 -> 0 | E49: =E8*0.9 -> 0
B50: Investment Costs | D50: =D9 -> 0 | E50: =E9*0.9 -> 0
B51: Fixed Capital | C51: Nos. | D51: =D10 -> 1 | E51: =E10*0.9 -> 900000 | F51: =D51*E51 -> 900000 | G51: =D51*E51 -> 900000 | H51: 0 | I51: 0 | J51: 0 | P51: =K51 -> 0
B52: Installment | C52: lumpsum | D52: =D11 -> 1 | E52: =E11*0.9 -> 270000 | F52: =D52*E52 -> 270000 | G52: =D52*E52 -> 270000 | H52: 0 | I52: 0 | J52: 0 | K52: 0
B53: Sub-total Investment | D53: =D12 -> 0 | E53: =E12*0.9 -> 0 | F53: =SUM(F51:F52) -> 1170000 | G53: =SUM(G51:G52) -> 1170000 | H53: =SUM(H51:H52) -> 0 | I53: =SUM(I51:I52) -> 0 | J53: =SUM(J51:J52) -> 0 | K53: =SUM(K51:K52) -> 0 | L53: =SUM(L51:L52) -> 0 | M53: =SUM(M51:M52) -> 0 | ... U53: =SUM(U51:U52) -> 0
...

Sheet Cross Ventilation Improvements
B1: FINANCIAL
C2: Unit | D2: Quantity | E2: Price | F2: Amount | G2: Year
B3: REVENUE | D3: With Project | G3: 1 | H3: =G3+1 -> 2 | I3: =H3+1 -> 3 | J3: =I3+1 -> 4 | K3: =J3+1 -> 5 | L3: =K3+1 -> 6 | M3: =L3+1 -> 7 | N3: =M3+1 -> 8 | O3: =N3+1 -> 9 | P3: =O3+1 -> 10 | Q3: 11 | R3: 12 | S3: 13 | T3: 14 | U3: 15
B4: Energy saved | C4: KWH/hr | D4: 1000 | E4: 2500 | H4: =I4 -> 2500000 | I4: =J4 -> 2500000 | J4: =D4*E4 -> 2500000 | K4: =J4*1.2 -> 3000000 | L4: =K4*1.2 -> 3600000 | M4: =L4*1.2 -> 4320000 | N4: =M4*1.2 -> 5184000 | O4: =N4*1.2 -> 6220800 | P4: =O4*1.2 -> 7464960 | Q4: =P4*1.2 -> 8957952 | R4: =Q4*1.2 -> 10749542 | ... U4: =T4*1.2 -> 18575209
B5: Time saved /productivity | C5: Hr | D5: 520 | E5: 100 | F5: =D5*E5 -> 52000 | G5: =F5 -> 52000 | H5: =F5 -> 52000 | I5: =H5 -> 52000 | J5: =I5 -> 52000 | K5: =J5 -> 52000 | L5: =K5 -> 52000 | M5: =L5 -> 52000 | N5: =M5 -> 52000 | O5: =N5 -> 52000 | P5: =O5 -> 52000 | ... U5: =T5 -> 52000
B6: Sub-total Revenue | F6: =SUM(F4:F5) -> 52000 | G6: =SUM(G4:G5) -> 52000 | H6: =SUM(H4:H5) -> 2552000 | I6: =SUM(I4:I5) -> 2552000 | J6: =SUM(J4:J5) -> 2552000 | K6: =SUM(K4:K5) -> 3052000 | L6: =SUM(L4:L5) -> 3652000 | M6: =SUM(M4:M5) -> 4372000 | ... U6: =SUM(U4:U5) -> 18627209
B8: CAPEX
B9: Investment Costs
B10: Cost of capital | C10: Nos. | D10: 500 | E10: 300 | F10: =D10*E10 -> 150000 | G10: =F10 -> 150000 | H10: =G10 -> 150000 | I10: 0 | J10: 0 | K10: 0
B11: Intallation | C11: lumpsum | D11: 1 | E11: 60000 | F11: =D11*E11 -> 60000 | G11: =F11 -> 60000 | H11: =G11 -> 60000 | I11: 0 | J11: 0 | K11: 0
B12: Sub-total Investment | F12: 0 | G12: 0 | H12: =SUM(H10:H11) -> 210000 | I12: =SUM(I10:I11) -> 0 | J12: =SUM(J10:J11) -> 0 | K12: =SUM(K10:K11) -> 0
F13: =D13*E13 -> 0
B14: OPEX | F14: =D14*E14 -> 0
B15: Wages and Labor | C15: MZK | D15: 10710 | E15: 1 | F15: =D15*E15 -> 10710 | G15: =F15 -> 10710 | H15: =F15 -> 10710 | I15: =H15 -> 10710 | J15: =I15 -> 10710 | K15: =J15 -> 10710 | L15: =K15 -> 10710 | M15: =L15 -> 10710 | N15: =M15 -> 10710 | O15: =N15 -> 10710 | P15: =O15 -> 10710 | ... T15: =S15 -> 10710 | U15: =T15*0.5 -> 5355
B16: Window and Vent Maintenance | C16: MZK | D16: 2000 | E16: 900 | F16: =D16*E16 -> 1800000 | G16: =F16 -> 1800000 | H16: =F16 -> 1800000 | I16: =H16 -> 1800000 | J16: =H16 -> 1800000 | K16: =J16 -> 1800000 | L16: =J16 -> 1800000 | M16: =L16 -> 1800000 | N16: =L16 -> 1800000 | O16: =N16 -> 1800000 | P16: =N16 -> 1800000 | Q16: =P16 -> 1800000 | R16: =P16 -> 1800000 | S16: =R16 -> 1800000 | T16: =R16 -> 1800000 | U16: =T16 -> 1800000
B17: Cleaning and Repair | C17: MZK | F17: 1000000 | G17: =F17 -> 1000000 | H17: =F17 -> 1000000 | I17: =H17 -> 1000000 | J17: =I17 -> 1000000 | K17: =J17 -> 1000000 | L17: =K17 -> 1000000 | M17: =L17 -> 1000000 | N17: =M17 -> 1000000 | O17: =N17 -> 1000000 | P17: =O17 -> 1000000 | ... U17: =T17 -> 1000000
B18: Ventilation Component Replacement | C18: MZK | F18: 2080000 | G18: =F18 -> 2080000 | H18: =G18 -> 2080000 | I18: =H18 -> 2080000 | J18: =I18 -> 2080000 | K18: =J18 -> 2080000 | L18: =K18 -> 2080000 | M18: =L18 -> 2080000 | N18: =M18 -> 2080000 | ... U18: =T18 -> 2080000
B19: Building Maintenance | C19: MZK | F19: 550000 | G19: =F19 -> 550000 | H19: =F19 -> 550000 | I19: =H19 -> 550000 | J19: =I19 -> 550000 | K19: =J19 -> 550000 | L19: =K19 -> 550000 | M19: =L19 -> 550000 | N19: =M19 -> 550000 | O19: =N19 -> 550000 | P19: =O19 -> 550000 | ... U19: =T19 -> 550000
B20: Sub-total for Operating costs | F20: =SUM(F15:F19) -> 5440710 | G20: =SUM(G15:G19) -> 5440710 | H20: =SUM(H15:H19) -> 5440710 | I20: =SUM(I15:I19) -> 5440710 | J20: =SUM(J15:J19) -> 5440710 | K20: =SUM(K15:K19) -> 5440710 | L20: =SUM(L15:L19) -> 5440710 | M20: =SUM(M15:M19) -> 5440710 | ... U20: =SUM(U15:U19) -> 5435355
B22: Fixed costs
B23: Depreciation | C23: MZK/annum | D23: 1 | E23: =E11/15 -> 4000 | F23: =D23*E23 -> 4000 | G23: =F23 -> 4000 | H23: =D23*E23 -> 4000 | I23: =H23 -> 4000 | J23: =I23 -> 4000 | K23: =J23 -> 4000 | L23: =K23 -> 4000 | M23: =L23 -> 4000 | N23: =M23 -> 4000 | O23: =N23 -> 4000 | P23: =O23 -> 4000 | ... U23: =T23 -> 4000 | V23: =SUM(H23:U23) -> 56000
B24: Sub-total for Fixed costs | F24: =F15 -> 10710 | G24: =G15 -> 10710 | H24: =H15 -> 10710 | I24: =I15 -> 10710 | J24: =J15 -> 10710 | K24: =K15 -> 10710 | L24: =L15 -> 10710 | M24: =M15 -> 10710 | ... U24: =U15 -> 5355
B25: TOTAL COSTS | F25: =F12+F20+F24 -> 5451420 | G25: =G12+G20+G24 -> 5451420 | H25: =H12+H20+H24 -> 5661420 | I25: =I12+I20+I24 -> 5451420 | J25: =J12+J20+J24 -> 5451420 | K25: =K12+K20+K24 -> 5451420 | L25: =L12+L20+L24 -> 5451420 | M25: =M12+M20+M24 -> 5451420 | ... U25: =U12+U20+U24 -> 5440710
B27: GROSS MARGIN | C27: MZK/annum | I27: =-(I6-I12-I20) -> 2888710 | J27: =J6-J12-J20 -> -2888710 | K27: =K6-K12-K20 -> -2388710 | L27: =L6-L12-L20 -> -1788710 | M27: =M6-M12-M20 -> -1068710 | N27: =N6-N12-N20 -> -204710 | O27: =O6-O12-O20 -> 832090 | P27: =P6-P12-P20 -> 2076250 | Q27: =Q6-Q12-Q20 -> 3569242 | ... U27: =U6-U12-U20 -> 13191854
B28: NET MARGIN | C28: MZK/annum | G28: =H28 -> -2878000 | H28: =I28 -> -2878000 | I28: =-(I27-I24) -> -2878000 | J28: =I28 -> -2878000 | K28: =K27-K24 -> -2399420 | L28: =L27-L24 -> -1799420 | M28: =(M27-M24) -> -1079420 | N28: =N27-N24 -> -215420 | O28: =O27-O24 -> 821380 | P28: =P27-P24 -> 2065540 | Q28: =Q27-Q24 -> 3558532 | R28: =R27-R24 -> 5350122.4 | S28: =S27-S24 -> 7500030.9 | T28: =T27-T24 -> 10079921 | U28: =U27-U24 -> 13186499
B29: FIRR | G29: =IRR(I28:U28) -> 0.16676295
B30: FNPV | G30: =-(NPV(0.1,G28:U28)) -> 202606.48
B41: ECONOMIC
C42: Unit | D42: Quantity | E42: Price | F42: Amount | G42: Year
B43: REVENUE | D43: With Project | G43: 1 | H43: =G43+1 -> 2 | I43: =H43+1 -> 3 | J43: =I43+1 -> 4 | K43: =J43+1 -> 5 | L43: =K43+1 -> 6 | M43: =L43+1 -> 7 | N43: =M43+1 -> 8 | O43: =N43+1 -> 9 | P43: =O43+1 -> 10 | Q43: 11 | R43: 12 | S43: 13 | T43: 14 | U43: 15
B44: Energy saved | C44: KWH/h | D44: =D4 -> 1000 | E44: =E4*0.9 -> 2250 | G44: 0 | H44: =F44 -> 0 | I44: =D44*E44*10 -> 22500000 | J44: =I44 -> 22500000 | K44: =J44 -> 22500000 | L44: =K44 -> 22500000 | M44: =L44 -> 22500000 | N44: =M44 -> 22500000 | O44: =N44 -> 22500000 | P44: =O44 -> 22500000 | Q44: =P44 -> 22500000 | ... U44: =T44 -> 22500000
B45: Time saved /productivity | C45: No | D45: =D5 -> 520 | E45: =E5*0.9 -> 90 | G45: =F45 -> 0 | H45: =F45 -> 0 | I45: =E45*D45 -> 46800 | J45: =I45 -> 46800 | K45: =J45 -> 46800 | L45: =K45 -> 46800 | M45: =L45 -> 46800 | N45: =M45 -> 46800 | O45: =N45 -> 46800 | P45: =O45 -> 46800 | Q45: =P45 -> 46800 | ... U45: =T45 -> 46800
B46: Sub-total Revenue | F46: =SUM(F44:F45) -> 0 | G46: =SUM(G44:G45) -> 0 | H46: =SUM(H44:H45) -> 0 | I46: =SUM(I44:I45) -> 22546800 | J46: =SUM(J44:J45) -> 22546800 | K46: =SUM(K44:K45) -> 22546800 | L46: =SUM(L44:L45) -> 22546800 | M46: =SUM(M44:M45) -> 22546800 | ... U46: =SUM(U44:U45) -> 22546800
B48: CAPEX
B49: Investment Costs
B50: Capital Investment | C50: Nos. | D50: =D10 -> 500 | E50: =E10*0.9 -> 270 | F50: =D50*E50 -> 135000 | G50: =D50*E50 -> 135000 | H50: =G50 -> 135000 | I50: 0 | J50: 0 | K50: 0
B51: Intallation cost | C51: lumpsum | D51: 1 | E51: =E11*0.9 -> 54000 | F51: =D51*E51 -> 54000 | G51: =D51*E51 -> 54000 | H51: =G51 -> 54000 | I51: 0 | J51: 0 | K51: 0
B52: Sub-total Investment | F52: =SUM(F50:F51) -> 189000 | G52: =SUM(G50:G51) -> 189000 | H52: =SUM(H50:H51) -> 189000 | I52: =SUM(I50:I51) -> 0 | J52: =SUM(J50:J51) -> 0 | K52: =SUM(K50:K51) -> 0
F53: =D53*E53 -> 0
B54: OPEX | F54: =D54*E54 -> 0
...

Sheet External Shading (Awnings, Over
B1: FINANCIAL
C2: Unit | D2: Quantity | E2: Price | F2: Amount | G2: Year
B3: REVENUE | G3: 1 | H3: =G3+1 -> 2 | I3: =H3+1 -> 3 | J3: =I3+1 -> 4 | K3: =J3+1 -> 5 | L3: =K3+1 -> 6 | M3: =L3+1 -> 7 | N3: =M3+1 -> 8 | O3: =N3+1 -> 9 | P3: =O3+1 -> 10 | Q3: 11 | R3: 12 | S3: 13 | T3: 14 | U3: 15
B4: Milk | C4: Liter | D4: 0 | E4: 0 | F4: =D4*E4 -> 0 | H4: =F4 -> 0 | I4: =F4 -> 0 | J4: =F4 -> 0 | K4: =J4 -> 0 | L4: =K4 -> 0 | M4: =L4 -> 0 | N4: =M4 -> 0 | O4: =N4 -> 0 | P4: =O4 -> 0 | Q4: =P4 -> 0 | R4: =Q4 -> 0 | ... U4: =T4 -> 0
B5: - Manure | C5: Bags | D5: 50 | E5: 1000 | F5: =D5*E5 -> 50000 | G5: =F5 -> 50000 | H5: =D5*E5 -> 50000 | I5: =D5*E5 -> 50000 | J5: =D5*E5 -> 50000 | K5: =J5 -> 50000 | L5: =K5 -> 50000 | M5: =L5 -> 50000 | N5: =M5 -> 50000 | O5: =N5 -> 50000 | P5: =O5 -> 50000 | Q5: =P5 -> 50000 | R5: =Q5 -> 50000 | ... U5: =T5 -> 50000
B6: Selling of animal | C6: Nos | D6: 2 | E6: 150000 | F6: =E6*D6 -> 300000 | J6: =F6 -> 300000 | K6: =J6 -> 300000 | L6: =K6 -> 300000 | M6: =L6 -> 300000 | N6: =J6 -> 300000 | O6: =K6 -> 300000 | P6: =L6 -> 300000 | Q6: =M6 -> 300000 | R6: =N6 -> 300000 | S6: =O6 -> 300000 | T6: =P6 -> 300000 | U6: =Q6 -> 300000
B7: Sub-total Revenue | F7: =SUM(F4:F6) -> 350000 | G7: =SUM(G4:G6) -> 50000 | H7: =SUM(H4:H6) -> 50000 | I7: =SUM(I4:I6) -> 50000 | J7: =SUM(J4:J6) -> 350000 | K7: =SUM(K4:K6) -> 350000 | L7: =SUM(L4:L6) -> 350000 | M7: =SUM(M4:M6) -> 350000 | ... U7: =SUM(U4:U6) -> 350000
B9: COSTS
B10: Investment Costs
B11: Animal Cost | C11: lumpsum | D11: 2 | E11: 100000 | F11: =D11*E11 -> 200000 | G11: =D11*E11 -> 200000 | H11: 0 | I11: 0 | J11: 0 | P11: =K11 -> 0
B12: Other Fixed Cost | C12: lumpsum | D12: 2 | E12: 80000 | F12: =D12*E12 -> 160000 | G12: =D12*E12 -> 160000 | H12: 0 | I12: 0 | J12: 0 | K12: 0
B13: Sub-total Investment | F13: =SUM(F11:F12) -> 360000 | G13: =SUM(G11:G12) -> 360000 | H13: =SUM(H11:H12) -> 0 | I13: =SUM(I11:I12) -> 0 | J13: =SUM(J11:J12) -> 0 | K13: =SUM(K11:K12) -> 0 | L13: =SUM(L11:L12) -> 0 | M13: =SUM(M11:M12) -> 0 | ... U13: =SUM(U11:U12) -> 0
F14: =D14*E14 -> 0
B15: Operating costs | F15: =D15*E15 -> 0
B16: Fooder (Hay and Grains & Seeds) | C16: G$ | D16: 2 | E16: 10000 | F16: =D16*E16 -> 20000 | G16: =F16 -> 20000 | H16: =F16 -> 20000 | I16: =H16 -> 20000 | J16: =I16 -> 20000 | K16: =J16 -> 20000 | L16: =K16 -> 20000 | M16: =L16 -> 20000 | N16: =M16 -> 20000 | O16: =N16 -> 20000 | P16: =O16 -> 20000 | ... U16: =T16 -> 20000
B17: Wages and Salary | C17: G$ | D17: 0 | E17: 1000 | F17: =15*E17 -> 15000 | G17: =F17 -> 15000 | H17: =F17 -> 15000 | I17: =H17 -> 15000 | J17: =I17 -> 15000 | K17: =J17 -> 15000 | L17: =K17 -> 15000 | M17: =L17 -> 15000 | N17: =M17 -> 15000 | O17: =N17 -> 15000 | P17: =O17 -> 15000 | ... U17: =T17 -> 15000
B18: Veterinary Expenses | C18: G$ | D18: 2 | E18: 10000 | F18: 3000 | G18: =F18 -> 3000 | H18: =D18*E18*1 -> 20000 | I18: =D18*E18*1 -> 20000 | J18: =D18*E18 -> 20000 | K18: =J18 -> 20000 | L18: =K18 -> 20000 | M18: =L18 -> 20000 | N18: =M18 -> 20000 | O18: =N18 -> 20000 | P18: =O18 -> 20000 | Q18: =P18 -> 20000 | R18: =Q18 -> 20000 | ... U18: =T18 -> 20000
B19: herd management and sanitation | C19: G$ | D19: 2 | E19: 300 | F19: =D19*E19 -> 600 | G19: =F19 -> 600 | H19: =F19 -> 600 | I19: =H19 -> 600 | J19: =I19 -> 600 | K19: =J19 -> 600 | L19: =K19 -> 600 | M19: =L19 -> 600 | N19: =M19 -> 600 | O19: =N19 -> 600 | P19: =O19 -> 600 | ... U19: =T19 -> 600
B20: Vaccination and medication | C20: G$ | D20: 2 | E20: 8000 | F20: =D20*E20 -> 16000 | G20: =F20 -> 16000 | H20: =G20 -> 16000 | I20: =H20 -> 16000 | J20: =I20 -> 16000 | K20: =J20 -> 16000 | L20: =K20 -> 16000 | M20: =L20 -> 16000 | N20: =M20 -> 16000 | ... U20: =T20 -> 16000
B21: coral maintenance | C21: G4 | D21: 1 | E21: 15000 | F21: =D21*E21 -> 15000 | G21: =F21 -> 15000 | H21: =F21 -> 15000 | I21: =F21 -> 15000 | J21: =F21 -> 15000 | K21: =J21 -> 15000 | L21: =K21 -> 15000 | M21: =L21 -> 15000 | N21: =M21 -> 15000 | O21: =N21 -> 15000 | P21: =O21 -> 15000 | Q21: =P21 -> 15000 | R21: =Q21 -> 15000 | ... U21: =T21 -> 15000
B22: Sub-total for Operating costs | F22: =SUM(F16:F21) -> 69600 | G22: =SUM(G16:G21) -> 69600 | H22: =SUM(H16:H21) -> 86600 | I22: =SUM(I16:I21) -> 86600 | J22: =SUM(J16:J21) -> 86600 | K22: =SUM(K16:K21) -> 86600 | L22: =SUM(L16:L21) -> 86600 | M22: =SUM(M16:M21) -> 86600 | ... U22: =SUM(U16:U21) -> 86600
B24: Fixed costs
B25: Depreciation | C25: G$/annum | D25: 1 | E25: =E12/15 -> 5333.3333 | F25: =D25*E25 -> 5333.3333 | G25: =F25 -> 5333.3333 | H25: =D25*E25 -> 5333.3333 | I25: =H25 -> 5333.3333 | J25: =I25 -> 5333.3333 | K25: =J25 -> 5333.3333 | L25: =K25 -> 5333.3333 | M25: =L25 -> 5333.3333 | N25: =M25 -> 5333.3333 | O25: =N25 -> 5333.3333 | P25: =O25 -> 5333.3333 | ... U25: =T25 -> 5333.3333 | V25: =SUM(H25:U25) -> 74666.667
B26: Sub-total for Fixed costs | F26: =SUM(F25:F25) -> 5333.3333 | G26: =SUM(G25:G25) -> 5333.3333 | H26: =SUM(H25:H25) -> 5333.3333 | I26: =SUM(I25:I25) -> 5333.3333 | J26: =SUM(J25:J25) -> 5333.3333 | K26: =SUM(K25:K25) -> 5333.3333 | L26: =SUM(L25:L25) -> 5333.3333 | M26: =SUM(M25:M25) -> 5333.3333 | ... U26: =SUM(U25:U25) -> 5333.3333
B27: TOTAL COSTS | F27: =F13+F22+F26 -> 434933.33 | G27: =G13+G22+G26 -> 434933.33 | H27: =H13+H22+H26 -> 91933.333 | I27: =I13+I22+I26 -> 91933.333 | J27: =J13+J22+J26 -> 91933.333 | K27: =K13+K22+K26 -> 91933.333 | L27: =L13+L22+L26 -> 91933.333 | M27: =M13+M22+M26 -> 91933.333 | ... U27: =U13+U22+U26 -> 91933.333
B29: GROSS MARGIN | C29: G$/annum | G29: =G7-G13-G22 -> -379600 | H29: =H7-H13-H22 -> -36600 | I29: =I7-I13-I22 -> -36600 | J29: =J7-J13-J22 -> 263400 | K29: =K7-K13-K22 -> 263400 | L29: =L7-L13-L22 -> 263400 | M29: =M7-M13-M22 -> 263400 | N29: =N7-N13-N22 -> 263400 | ... U29: =U7-U13-U22 -> 263400
B30: NET MARGIN BEFORE PROFIT TAX | C30: G$/annum | G30: =G29-G26 -> -384933.33 | H30: =H29-H26 -> -41933.333 | I30: =I29-I26 -> -41933.333 | J30: =J29-J26 -> 258066.67 | K30: =K29-K26 -> 258066.67 | L30: =L29-L26 -> 258066.67 | M30: =M29-M26 -> 258066.67 | N30: =N29-N26 -> 258066.67 | ... U30: =U29-U26 -> 258066.67
B31: FIRR | G31: =IRR(G30:U30) -> 0.32300371
B32: FNPV | G32: =NPV(0.1,G30:U30) -> 905001.81
B34: ECONOMIC
C35: Unit | D35: Quantity | E35: Price | F35: Amount | G35: Year
B36: REVENUE | G36: 1 | H36: =G36+1 -> 2 | I36: =H36+1 -> 3 | J36: =I36+1 -> 4 | K36: =J36+1 -> 5 | L36: =K36+1 -> 6 | M36: =L36+1 -> 7 | N36: =M36+1 -> 8 | O36: =N36+1 -> 9 | P36: =O36+1 -> 10 | Q36: 11 | R36: 12 | S36: 13 | T36: 14 | U36: 15
B37: Milk | C37: Liter | D37: 0 | E37: =E4*0.9 -> 0 | F37: =D37*E37 -> 0 | H37: =F37 -> 0 | I37: =F37 -> 0 | J37: =F37 -> 0 | K37: =J37 -> 0 | L37: =K37 -> 0 | M37: =L37 -> 0 | N37: =M37 -> 0 | O37: =N37 -> 0 | P37: =O37 -> 0 | Q37: =P37 -> 0 | R37: =Q37 -> 0 | ... U37: =T37 -> 0
B38: - Manure | C38: Bags | D38: =D5 -> 50 | E38: =E5*0.9 -> 900 | F38: =D38*E38 -> 45000 | G38: =F38 -> 45000 | H38: =D38*E38 -> 45000 | I38: =D38*E38 -> 45000 | J38: =D38*E38 -> 45000 | K38: =J38 -> 45000 | L38: =K38 -> 45000 | M38: =L38 -> 45000 | N38: =M38 -> 45000 | O38: =N38 -> 45000 | P38: =O38 -> 45000 | Q38: =P38 -> 45000 | R38: =Q38 -> 45000 | ... U38: =T38 -> 45000
B39: Selling of animal | C39: Nos. | D39: =D6 -> 2 | E39: =E6 -> 150000 | F39: =D39*E39 -> 300000 | G39: =F39 -> 300000 | H39: =G39 -> 300000 | I39: =H39 -> 300000 | J39: =I39 -> 300000 | K39: =J39 -> 300000 | L39: =K39 -> 300000 | M39: =L39 -> 300000 | N39: =M39 -> 300000 | ... P39: =O39 -> 300000 | U39: =P39 -> 300000
B40: Sub-total Revenue | D40: =D7 -> 0 | E40: =E7*0.9 -> 0 | F40: =SUM(F37:F39) -> 345000 | G40: =SUM(G37:G39) -> 345000 | H40: =SUM(H37:H39) -> 345000 | I40: =SUM(I37:I39) -> 345000 | J40: =SUM(J37:J39) -> 345000 | K40: =SUM(K37:K39) -> 345000 | L40: =SUM(L37:L39) -> 345000 | M40: =SUM(M37:M39) -> 345000 | ... U40: =SUM(U37:U39) -> 345000
D41: =D8 -> 0 | E41: =E8*0.9 -> 0
B42: COSTS | D42: =D9 -> 0 | E42: =E9*0.9 -> 0
B43: Investment Costs | D43: =D10 -> 0 | E43: =E10*0.9 -> 0
B44: Animal Cost | C44: Nos. | D44: =D11 -> 2 | E44: =E11*0.9 -> 90000 | F44: =D44*E44 -> 180000 | G44: =D44*E44 -> 180000 | H44: 0 | I44: 0 | J44: 0 | P44: =K44 -> 0
...

Sheet Efficient Fans (DC or Energy-Ef
B1: FINANCIAL
C2: Unit | D2: Quantity | E2: Price | F2: Amount | G2: Year
B3: REVENUE | G3: 1 | H3: =G3+1 -> 2 | I3: =H3+1 -> 3 | J3: =I3+1 -> 4 | K3: =J3+1 -> 5 | L3: =K3+1 -> 6 | M3: =L3+1 -> 7 | N3: =M3+1 -> 8 | O3: =N3+1 -> 9 | P3: =O3+1 -> 10 | Q3: 11 | R3: 12 | S3: 13 | T3: 14 | U3: 15
B4: Sales from cassava bread | C4: kg | D4: 8000 | E4: 600 | F4: 0 | G4: 0 | H4: =I4 -> 4800000 | I4: =J4 -> 4800000 | J4: =D4*E4 -> 4800000 | K4: =J4 -> 4800000 | L4: =K4 -> 4800000 | M4: =L4 -> 4800000 | N4: =M4 -> 4800000 | O4: =N4 -> 4800000 | P4: =O4 -> 4800000 | Q4: =P4 -> 4800000 | R4: =Q4 -> 4800000 | ... U4: =T4 -> 4800000
B5: Sales from other diversification (Cassava jam, Cassava chips, Cassava cake) | C5: Lumpsum | D5: 1 | E5: 350000 | F5: 0 | H5: =E5 -> 350000 | I5: =E5 -> 350000 | J5: =I5 -> 350000 | K5: =J5 -> 350000 | L5: =K5 -> 350000 | M5: =L5 -> 350000 | N5: =M5 -> 350000 | O5: =N5 -> 350000 | P5: =O5 -> 350000 | Q5: =P5 -> 350000 | ... U5: =T5 -> 350000
K6: =J6 -> 0 | L6: =K6 -> 0 | M6: =L6 -> 0 | N6: =M6 -> 0 | O6: =N6 -> 0 | P6: =O6 -> 0 | Q6: =P6 -> 0 | R6: =Q6 -> 0 | ... U6: =T6 -> 0
G7: =F7 -> 0 | H7: =F7 -> 0 | I7: =G7 -> 0 | J7: =H7 -> 0 | K7: =J7 -> 0 | L7: =K7 -> 0 | M7: =L7 -> 0 | N7: =M7 -> 0 | O7: =N7 -> 0 | P7: =O7 -> 0 | Q7: =P7 -> 0 | R7: =Q7 -> 0 | ... U7: =T7 -> 0
B8: Sub-total Revenue | F8: =SUM(F4:F7) -> 0 | G8: =SUM(G4:G7) -> 0 | H8: =SUM(H4:H7) -> 5150000 | I8: =SUM(I4:I7) -> 5150000 | J8: =SUM(J4:J7) -> 5150000 | K8: =SUM(K4:K7) -> 5150000 | L8: =SUM(L4:L7) -> 5150000 | M8: =SUM(M4:M7) -> 5150000 | ... U8: =SUM(U4:U7) -> 5150000
B10: COSTS
B11: Investment Costs
B12: Fixed Capital, buliding construction and other equipment | C12: ha | D12: 10 | E12: 300000 | F12: =D12*E12 -> 3000000 | G12: =D12*E12 -> 3000000 | H12: =G12 -> 3000000 | I12: 0 | L12: 10000 | O12: 10000 | R12: 10000 | U12: 10000
B13: Sub-total Investment | F13: =SUM(F12:F12) -> 3000000 | G13: =SUM(G12:G12) -> 3000000 | H13: =SUM(H12:H12) -> 3000000 | I13: =SUM(I12:I12) -> 0 | J13: =SUM(J12:J12) -> 0 | K13: =SUM(K12:K12) -> 0 | L13: =SUM(L12:L12) -> 10000 | M13: =SUM(M12:M12) -> 0 | ... U13: =SUM(U12:U12) -> 10000
F14: =D14*E14 -> 0
B15: Operating costs | F15: =D15*E15 -> 0
B16: Raw materials | C16: G$ | D16: 10 | E16: 1000 | F16: =E16*D16 -> 10000 | G16: =F16 -> 10000 | H16: =G16 -> 10000 | I16: =H16 -> 10000 | J16: =I16 -> 10000 | K16: =J16 -> 10000 | L16: =K16 -> 10000 | M16: =L16 -> 10000 | N16: =M16 -> 10000 | ... U16: =T16 -> 10000
B17: Wages and salary | C17: G$ | D17: 200 | E17: 1500 | F17: =D17*E17 -> 300000 | G17: =F17 -> 300000 | H17: =G17 -> 300000 | I17: =H17 -> 300000 | J17: =I17 -> 300000 | K17: =J17 -> 300000 | L17: =K17 -> 300000 | M17: =L17 -> 300000 | N17: =M17 -> 300000 | ... U17: =T17 -> 300000
B18: other | C18: G$ | F18: =J4*0.4 -> 1920000 | G18: =F18 -> 1920000 | H18: =G18 -> 1920000 | I18: =H18 -> 1920000 | J18: =J4*0.75 -> 3600000 | K18: =J18 -> 3600000 | L18: =K18 -> 3600000 | M18: =L18 -> 3600000 | N18: =M18 -> 3600000 | O18: =N18 -> 3600000 | P18: =O18 -> 3600000 | Q18: =P18 -> 3600000 | R18: =Q18 -> 3600000 | ... U18: =T18 -> 3600000
B19: Transportation | C19: G$ | F19: 905000 | G19: =F19 -> 905000 | H19: =G19 -> 905000 | I19: =H19 -> 905000 | J19: 10000 | K19: =J19 -> 10000 | L19: =K19 -> 10000 | M19: =L19 -> 10000 | N19: =M19 -> 10000 | O19: =N19 -> 10000 | P19: =O19 -> 10000 | Q19: =P19 -> 10000 | R19: =Q19 -> 10000 | ... U19: =T19 -> 10000
B20: equipment | C20: G$ | F20: 900000 | G20: =F20 -> 900000 | H20: =G20 -> 900000 | I20: =H20 -> 900000 | J20: =I20 -> 900000 | K20: =J20 -> 900000 | L20: =K20 -> 900000 | M20: =L20 -> 900000 | N20: =M20 -> 900000 | ... U20: =T20 -> 900000
B21: Damage | C21: G$ | F21: 8900 | G21: =F21 -> 8900 | H21: =G21 -> 8900 | I21: =H21 -> 8900 | J21: =I21 -> 8900 | K21: =J21 -> 8900 | L21: =K21 -> 8900 | M21: =L21 -> 8900 | N21: =M21 -> 8900 | ... U21: =T21 -> 8900
B23: Sub-total for Operating costs | F23: =SUM(F16:F22) -> 4043900 | G23: =SUM(G16:G22) -> 4043900 | H23: =SUM(H16:H22) -> 4043900 | I23: =SUM(I16:I22) -> 4043900 | J23: =SUM(J16:J22) -> 4828900 | K23: =SUM(K16:K22) -> 4828900 | L23: =SUM(L16:L22) -> 4828900 | M23: =SUM(M16:M22) -> 4828900 | ... U23: =SUM(U16:U22) -> 4828900
B25: Fixed costs
B26: Depreciation | C26: G$/anuum | D26: 1 | E26: =E12/15 -> 20000 | F26: =D26*E26 -> 20000 | H26: =D26*E26 -> 20000 | I26: =H26 -> 20000 | J26: =I26 -> 20000 | K26: =J26 -> 20000 | L26: =K26 -> 20000 | M26: =L26 -> 20000 | N26: =M26 -> 20000 | O26: =N26 -> 20000 | P26: =O26 -> 20000 | ... U26: =T26 -> 20000 | V26: =SUM(H26:U26) -> 280000
B27: Sub-total for Fixed costs | F27: =SUM(F26:F26) -> 20000 | G27: =SUM(G26:G26) -> 0 | H27: =SUM(H26:H26) -> 20000 | I27: =SUM(I26:I26) -> 20000 | J27: =SUM(J26:J26) -> 20000 | K27: =SUM(K26:K26) -> 20000 | L27: =SUM(L26:L26) -> 20000 | M27: =SUM(M26:M26) -> 20000 | ... U27: =SUM(U26:U26) -> 20000
B28: TOTAL COSTS | F28: =F13+F23+F27 -> 7063900 | G28: =G13+G23+G27 -> 7043900 | H28: =H13+H23+H27 -> 7063900 | I28: =I13+I23+I27 -> 4063900 | J28: =J13+J23+J27 -> 4848900 | K28: =K13+K23+K27 -> 4848900 | L28: =L13+L23+L27 -> 4858900 | M28: =M13+M23+M27 -> 4848900 | ... U28: =U13+U23+U27 -> 4858900
B30: GROSS MARGIN | C30: G$s/annum | G30: =G8-G13-G23 -> -7043900 | H30: =H8-H13-H23 -> -1893900 | I30: =I8-I13-I23 -> 1106100 | J30: =J8-J13-J23 -> 321100 | K30: =K8-K13-K23 -> 321100 | L30: =L8-L13-L23 -> 311100 | M30: =M8-M13-M23 -> 321100 | N30: =N8-N13-N23 -> 321100 | ... U30: =U8-U13-U23 -> 311100
B31: NET MARGIN BEFORE PROFIT TAX | C31: G$s/annum | G31: =G30-G27 -> -7043900 | H31: =H30-H27 -> -1913900 | I31: =I30-I27 -> 1086100 | J31: =J30-J27 -> 301100 | K31: =K30-K27 -> 301100 | L31: =L30-L27 -> 291100 | M31: =M30-M27 -> 301100 | N31: =N30-N27 -> 301100 | ... U31: =U30-U27 -> 291100
B32: FIRR | G32: =IRR(H31:U31) -> 0.21726914
B33: FNPV | G33: =NPV(0.1,G31:U31) -> -5643344.5
B36: ECONOMIC
C37: Unit | D37: Quantity | E37: Price | F37: Amount | G37: Year
B38: REVENUE | G38: 1 | H38: =G38+1 -> 2 | I38: =H38+1 -> 3 | J38: =I38+1 -> 4 | K38: =J38+1 -> 5 | L38: =K38+1 -> 6 | M38: =L38+1 -> 7 | N38: =M38+1 -> 8 | O38: =N38+1 -> 9 | P38: =O38+1 -> 10 | Q38: 11 | R38: 12 | S38: 13 | T38: 14 | U38: 15
B39: Sales | C39: lumpsum | D39: =D4 -> 8000 | E39: =E4*1.1 -> 660 | F39: =F4*0.9 -> 0 | G39: =F39 -> 0 | H39: =J39 -> 4320000 | I39: =J39 -> 4320000 | J39: =J4*0.9 -> 4320000 | K39: =J39 -> 4320000 | L39: =K39 -> 4320000 | M39: =L39 -> 4320000 | N39: =M39 -> 4320000 | O39: =N39 -> 4320000 | P39: =O39 -> 4320000 | Q39: =P39 -> 4320000 | R39: =Q39 -> 4320000 | ... U39: =T39 -> 4320000
B40: Income from gum arabic export | C40: lumpsum | D40: 1 | E40: =E5 -> 350000 | F40: =F7*0.9 -> 0 | G40: =F40 -> 0 | H40: =J40 -> 315000 | I40: =H40 -> 315000 | J40: =E40*0.9 -> 315000 | K40: =J40 -> 315000 | L40: =K40 -> 315000 | M40: =L40 -> 315000 | N40: =M40 -> 315000 | O40: =N40 -> 315000 | P40: =O40 -> 315000 | Q40: =P40 -> 315000 | R40: =Q40 -> 315000 | ... U40: =T40 -> 315000
J41: =E41*0.9 -> 0 | K41: =F41*0.9 -> 0 | L41: =G41*0.9 -> 0 | M41: =H41*0.9 -> 0 | N41: =I41*0.9 -> 0 | O41: =J41*0.9 -> 0 | P41: =K41*0.9 -> 0 | Q41: =L41*0.9 -> 0 | ... U41: =P41*0.9 -> 0
B42: Sub-total Revenue | D42: =D8 -> 0 | E42: =E8*0.9 -> 0 | F42: =SUM(F39:F41) -> 0 | G42: =SUM(G39:G41) -> 0 | H42: =SUM(H39:H41) -> 4635000 | I42: =I8 -> 5150000 | J42: =SUM(J39:J41) -> 4635000 | K42: =SUM(K39:K41) -> 4635000 | L42: =SUM(L39:L41) -> 4635000 | M42: =SUM(M39:M41) -> 4635000 | N42: =SUM(N39:N41) -> 4635000 | O42: =SUM(O39:O41) -> 4635000 | P42: =SUM(P39:P41) -> 4635000 | Q42: =SUM(Q39:Q41) -> 4635000 | ... U42: =SUM(U39:U41) -> 4635000
D43: =D9 -> 0 | E43: =E9*0.9 -> 0
B44: COSTS | D44: =D10 -> 0 | E44: =E10*0.9 -> 0
B45: Investment Costs | D45: =D11 -> 0 | E45: =E11*0.9 -> 0
B46: Fixed Capital, buliding construction and other equipment | C46: Nos. | D46: 10 | E46: =E12*0.9 -> 270000 | F46: =F12*0.9 -> 2700000 | G46: =G12 -> 3000000 | I46: 0 | J46: 0 | P46: =K46 -> 0
...

Sheet Honey
B1: FINANCIAL
C2: Unit | D2: Quantity | E2: Price | F2: Amount | G2: Year
B3: REVENUE | G3: 1 | H3: =G3+1 -> 2 | I3: =H3+1 -> 3 | J3: =I3+1 -> 4 | K3: =J3+1 -> 5 | L3: =K3+1 -> 6 | M3: =L3+1 -> 7 | N3: =M3+1 -> 8 | O3: =N3+1 -> 9 | P3: =O3+1 -> 10 | Q3: 11 | R3: 12 | S3: 13 | T3: 14 | U3: 15
B4: Sales | C4: lumpsum | F4: 600000 | G4: =F4*0.5 -> 300000 | H4: =F4 -> 600000 | I4: =F4 -> 600000 | J4: =F4 -> 600000 | K4: =J4 -> 600000 | L4: =K4 -> 600000 | M4: =L4 -> 600000 | N4: =M4 -> 600000 | O4: =N4 -> 600000 | P4: =O4 -> 600000 | Q4: =P4 -> 600000 | R4: =Q4 -> 600000 | ... U4: =T4 -> 600000
B5: Other income | C5: lumpsum | F5: 50000 | H5: =F5 -> 50000 | I5: =H5 -> 50000 | J5: =H5 -> 50000 | K5: =J5 -> 50000 | L5: =K5 -> 50000 | M5: =L5 -> 50000 | N5: =M5 -> 50000 | O5: =N5 -> 50000 | P5: =O5 -> 50000 | Q5: =P5 -> 50000 | R5: =Q5 -> 50000 | ... U5: =T5 -> 50000
B6: Sub-total Revenue | F6: =SUM(F4:F5) -> 650000 | G6: =SUM(G4:G5) -> 300000 | H6: =SUM(H4:H5) -> 650000 | I6: =SUM(I4:I5) -> 650000 | J6: =SUM(J4:J5) -> 650000 | K6: =SUM(K4:K5) -> 650000 | L6: =SUM(L4:L5) -> 650000 | M6: =SUM(M4:M5) -> 650000 | ... U6: =SUM(U4:U5) -> 650000
B8: COSTS
B9: Investment Costs
B10: Fixed Capital | C10: lumpsum | D10: 1 | E10: 100000 | F10: =D10*E10 -> 100000 | G10: =D10*E10 -> 100000 | H10: 0 | I10: 0 | J10: 0 | P10: =K10 -> 0
B11: Cash in hand | C11: lumpsum | D11: 1 | E11: 20000 | F11: =D11*E11 -> 20000 | G11: =D11*E11 -> 20000 | H11: 0 | I11: 0 | J11: 0 | K11: 0
B12: Sub-total Investment | F12: =SUM(F10:F11) -> 120000 | G12: =SUM(G10:G11) -> 120000 | H12: =SUM(H10:H11) -> 0 | I12: =SUM(I10:I11) -> 0 | J12: =SUM(J10:J11) -> 0 | K12: =SUM(K10:K11) -> 0 | L12: =SUM(L10:L11) -> 0 | M12: =SUM(M10:M11) -> 0 | ... U12: =SUM(U10:U11) -> 0
F13: =D13*E13 -> 0
B14: Operating costs | F14: =D14*E14 -> 0
B15: Material Cost | C15: G$ | F15: =F4*0.75 -> 450000 | G15: =F15*0.5 -> 225000 | H15: =F15 -> 450000 | I15: =H15 -> 450000 | J15: =I15 -> 450000 | K15: =J15 -> 450000 | L15: =K15 -> 450000 | M15: =L15 -> 450000 | N15: =M15 -> 450000 | O15: =N15 -> 450000 | P15: =O15 -> 450000 | ... U15: =T15 -> 450000
B16: Other direct cost | C16: G$ | F16: 30000 | H16: =F16 -> 30000 | I16: =H16 -> 30000 | J16: =I16 -> 30000 | K16: =J16 -> 30000 | L16: =K16 -> 30000 | M16: =L16 -> 30000 | N16: =M16 -> 30000 | O16: =N16 -> 30000 | P16: =O16 -> 30000 | ... U16: =T16 -> 30000
B17: Wages and Salary | C17: G$ | D17: 200 | E17: 450 | F17: =D17*E17 -> 90000 | G17: =F17*0.75 -> 67500 | H17: =F17 -> 90000 | I17: =H17 -> 90000 | J17: =I17 -> 90000 | K17: =J17 -> 90000 | L17: =K17 -> 90000 | M17: =L17 -> 90000 | N17: =M17 -> 90000 | O17: =N17 -> 90000 | P17: =O17 -> 90000 | ... U17: =T17 -> 90000
B18: Rent | C18: G$ | F18: 10000 | G18: =F18 -> 10000 | H18: =G18 -> 10000 | I18: =H18 -> 10000 | J18: =I18 -> 10000 | K18: =J18 -> 10000 | L18: =K18 -> 10000 | M18: =L18 -> 10000 | N18: =M18 -> 10000 | ... U18: =T18 -> 10000
B19: Other equipment cost | C19: G$ | F19: =F4*0.01 -> 6000 | G19: =F19 -> 6000 | H19: =F19 -> 6000 | I19: =H19 -> 6000 | J19: =I19 -> 6000 | K19: =J19 -> 6000 | L19: =K19 -> 6000 | M19: =L19 -> 6000 | N19: =M19 -> 6000 | O19: =N19 -> 6000 | P19: =O19 -> 6000 | ... U19: =T19 -> 6000
B20: Damage | C20: G$ | F20: =F4*0.01 -> 6000 | G20: =F20 -> 6000 | H20: =G20 -> 6000 | I20: =H20 -> 6000 | J20: =I20 -> 6000 | K20: =J20 -> 6000 | L20: =K20 -> 6000 | M20: =L20 -> 6000 | N20: =M20 -> 6000 | ... U20: =T20 -> 6000
B22: Sub-total for Operating costs | F22: =SUM(F15:F21) -> 592000 | G22: =SUM(G15:G21) -> 314500 | H22: =SUM(H15:H21) -> 592000 | I22: =SUM(I15:I21) -> 592000 | J22: =SUM(J15:J21) -> 592000 | K22: =SUM(K15:K21) -> 592000 | L22: =SUM(L15:L21) -> 592000 | M22: =SUM(M15:M21) -> 592000 | ... U22: =SUM(U15:U21) -> 592000
B24: Fixed costs
B25: Depreciation | C25: G$/annum | D25: 1 | E25: =E10/15 -> 6666.6667 | F25: =D25*E25 -> 6666.6667 | G25: =F25 -> 6666.6667 | H25: =D25*E25 -> 6666.6667 | I25: =H25 -> 6666.6667 | J25: =I25 -> 6666.6667 | K25: =J25 -> 6666.6667 | L25: =K25 -> 6666.6667 | M25: =L25 -> 6666.6667 | N25: =M25 -> 6666.6667 | O25: =N25 -> 6666.6667 | P25: =O25 -> 6666.6667 | ... U25: =T25 -> 6666.6667 | V25: =SUM(H25:U25) -> 93333.333
B26: Sub-total for Fixed costs | F26: =SUM(F25:F25) -> 6666.6667 | G26: =SUM(G25:G25) -> 6666.6667 | H26: =SUM(H25:H25) -> 6666.6667 | I26: =SUM(I25:I25) -> 6666.6667 | J26: =SUM(J25:J25) -> 6666.6667 | K26: =SUM(K25:K25) -> 6666.6667 | L26: =SUM(L25:L25) -> 6666.6667 | M26: =SUM(M25:M25) -> 6666.6667 | ... U26: =SUM(U25:U25) -> 6666.6667
B27: TOTAL COSTS | F27: =F12+F22+F26 -> 718666.67 | G27: =G12+G22+G26 -> 441166.67 | H27: =H12+H22+H26 -> 598666.67 | I27: =I12+I22+I26 -> 598666.67 | J27: =J12+J22+J26 -> 598666.67 | K27: =K12+K22+K26 -> 598666.67 | L27: =L12+L22+L26 -> 598666.67 | M27: =M12+M22+M26 -> 598666.67 | ... U27: =U12+U22+U26 -> 598666.67
B29: GROSS MARGIN | C29: G$/annum | G29: =G6-G12-G22 -> -134500 | H29: =H6-H12-H22 -> 58000 | I29: =I6-I12-I22 -> 58000 | J29: =J6-J12-J22 -> 58000 | K29: =K6-K12-K22 -> 58000 | L29: =L6-L12-L22 -> 58000 | M29: =M6-M12-M22 -> 58000 | N29: =N6-N12-N22 -> 58000 | ... U29: =U6-U12-U22 -> 58000
B30: NET MARGIN BEFORE PROFIT TAX | C30: G$/annum | G30: =G29-G26 -> -141166.67 | H30: =H29-H26 -> 51333.333 | I30: =I29-I26 -> 51333.333 | J30: =J29-J26 -> 51333.333 | K30: =K29-K26 -> 51333.333 | L30: =L29-L26 -> 51333.333 | M30: =M29-M26 -> 51333.333 | N30: =N29-N26 -> 51333.333 | ... U30: =U29-U26 -> 51333.333
B31: FIRR | G31: =IRR(G30:U30) -> 0.35865753
B32: FNPV | G32: =NPV(0.1,G30:U30) -> 215445.41
B40: ECONOMIC
C41: Unit | D41: Quantity | E41: Price | F41: Amount | G41: Year
B42: REVENUE | G42: 1 | H42: =G42+1 -> 2 | I42: =H42+1 -> 3 | J42: =I42+1 -> 4 | K42: =J42+1 -> 5 | L42: =K42+1 -> 6 | M42: =L42+1 -> 7 | N42: =M42+1 -> 8 | O42: =N42+1 -> 9 | P42: =O42+1 -> 10 | Q42: 11 | R42: 12 | S42: 13 | T42: 14 | U42: 15
B43: Sales | C43: lumpsum | F43: =F4*0.9 -> 540000 | G43: =F43*0.5 -> 270000 | H43: =F43 -> 540000 | I43: =F43 -> 540000 | J43: =F43 -> 540000 | K43: =J43 -> 540000 | L43: =K43 -> 540000 | M43: =L43 -> 540000 | N43: =M43 -> 540000 | O43: =N43 -> 540000 | P43: =O43 -> 540000 | Q43: =P43 -> 540000 | R43: =Q43 -> 540000 | ... U43: =T43 -> 540000
B44: Other income | C44: lumpsum | F44: =F5*0.9 -> 45000 | H44: =F44 -> 45000 | I44: =H44 -> 45000 | J44: =I44 -> 45000 | K44: =J44 -> 45000 | L44: =K44 -> 45000 | M44: =L44 -> 45000 | N44: =M44 -> 45000 | O44: =N44 -> 45000 | P44: =O44 -> 45000 | ... U44: =T44 -> 45000
B46: Sub-total Revenue | D46: =D6 -> 0 | E46: =E6*0.9 -> 0 | F46: =SUM(F43:F45) -> 585000 | G46: =SUM(G43:G45) -> 270000 | H46: =SUM(H43:H45) -> 585000 | I46: =SUM(I43:I45) -> 585000 | J46: =SUM(J43:J45) -> 585000 | K46: =SUM(K43:K45) -> 585000 | L46: =SUM(L43:L45) -> 585000 | M46: =SUM(M43:M45) -> 585000 | ... U46: =SUM(U43:U45) -> 585000
D47: =D7 -> 0 | E47: =E7*0.9 -> 0
B48: COSTS | D48: =D8 -> 0 | E48: =E8*0.9 -> 0
B49: Investment Costs | D49: =D9 -> 0 | E49: =E9*0.9 -> 0
B50: Fixed Capital | C50: Nos. | D50: =D10 -> 1 | E50: =E10*0.9 -> 90000 | F50: =D50*E50 -> 90000 | G50: =D50*E50 -> 90000 | H50: 0 | I50: 0 | J50: 0 | P50: =K50 -> 0
B51: Cash in hand | C51: lumpsum | D51: =D11 -> 1 | E51: =E11*0.9 -> 18000 | F51: =D51*E51 -> 18000 | G51: =D51*E51 -> 18000 | H51: 0 | I51: 0 | J51: 0 | K51: 0
B52: Sub-total Investment | D52: =D12 -> 0 | E52: =E12*0.9 -> 0 | F52: =SUM(F50:F51) -> 108000 | G52: =SUM(G50:G51) -> 108000 | H52: =SUM(H50:H51) -> 0 | I52: =SUM(I50:I51) -> 0 | J52: =SUM(J50:J51) -> 0 | K52: =SUM(K50:K51) -> 0 | L52: =SUM(L50:L51) -> 0 | M52: =SUM(M50:M51) -> 0 | ... U52: =SUM(U50:U51) -> 0
...

Sheet School kitchen gardening
B1: FINANCIAL
C2: Unit | D2: Quantity | E2: Price | F2: Amount | G2: Year
B3: REVENUE | G3: 1 | H3: =G3+1 -> 2 | I3: =H3+1 -> 3 | J3: =I3+1 -> 4 | K3: =J3+1 -> 5 | L3: =K3+1 -> 6 | M3: =L3+1 -> 7 | N3: =M3+1 -> 8 | O3: =N3+1 -> 9 | P3: =O3+1 -> 10 | Q3: 11 | R3: 12 | S3: 13 | T3: 14 | U3: 15
B4: Sales of vegetable | C4: lumpsum | F4: 200000 | G4: =F4 -> 200000 | H4: =F4 -> 200000 | I4: =F4 -> 200000 | J4: =F4 -> 200000 | K4: =J4 -> 200000 | L4: =K4 -> 200000 | M4: =L4 -> 200000 | N4: =M4 -> 200000 | O4: =N4 -> 200000 | P4: =O4 -> 200000 | Q4: =P4 -> 200000 | R4: =Q4 -> 200000 | ... U4: =T4 -> 200000
B5: Sub-total Revenue | F5: =SUM(F4:F4) -> 200000 | G5: =SUM(G4:G4) -> 200000 | H5: =SUM(H4:H4) -> 200000 | I5: =SUM(I4:I4) -> 200000 | J5: =SUM(J4:J4) -> 200000 | K5: =SUM(K4:K4) -> 200000 | L5: =SUM(L4:L4) -> 200000 | M5: =SUM(M4:M4) -> 200000 | ... U5: =SUM(U4:U4) -> 200000
B7: COSTS
B8: Investment Costs
B9: Fixed Capital | C9: lumpsum | D9: 1 | E9: 400000 | F9: =D9*E9 -> 400000 | G9: =D9*E9 -> 400000 | H9: 0 | I9: 10000 | L9: 10000 | O9: 10000 | R9: 10000 | U9: 10000
B10: Sub-total Investment | F10: =SUM(F9:F9) -> 400000 | G10: =SUM(G9:G9) -> 400000 | H10: =SUM(H9:H9) -> 0 | I10: =SUM(I9:I9) -> 10000 | J10: =SUM(J9:J9) -> 0 | K10: =SUM(K9:K9) -> 0 | L10: =SUM(L9:L9) -> 10000 | M10: =SUM(M9:M9) -> 0 | ... U10: =SUM(U9:U9) -> 10000
F11: =D11*E11 -> 0
B12: Operating costs | F12: =D12*E12 -> 0
B13: Seed cost | C13: G$ | F13: 15000 | G13: =F13 -> 15000 | H13: =G13 -> 15000 | I13: =H13 -> 15000 | J13: =I13 -> 15000 | K13: =J13 -> 15000 | L13: =K13 -> 15000 | M13: =L13 -> 15000 | N13: =M13 -> 15000 | ... U13: =T13 -> 15000
B14: Irrigation | C14: G$ | F14: 15000 | G14: =F14 -> 15000 | H14: =G14 -> 15000 | I14: =H14 -> 15000 | J14: =I14 -> 15000 | K14: =J14 -> 15000 | L14: =K14 -> 15000 | M14: =L14 -> 15000 | N14: =M14 -> 15000 | ... U14: =T14 -> 15000
B15: Wages and Salary | C15: G$ | F15: 10000 | G15: =F15 -> 10000 | H15: =G15 -> 10000 | I15: =H15 -> 10000 | J15: =I15 -> 10000 | K15: =J15 -> 10000 | L15: =K15 -> 10000 | M15: =L15 -> 10000 | N15: =M15 -> 10000 | ... U15: =T15 -> 10000
B16: Transportation | C16: G$ | F16: 56000 | G16: =F16 -> 56000 | H16: =G16 -> 56000 | I16: =H16 -> 56000 | J16: =I16 -> 56000 | K16: =J16 -> 56000 | L16: =K16 -> 56000 | M16: =L16 -> 56000 | N16: =M16 -> 56000 | ... U16: =T16 -> 56000
B18: Damage | C18: G$ | F18: 8900 | G18: =F18 -> 8900 | H18: =G18 -> 8900 | I18: =H18 -> 8900 | J18: =I18 -> 8900 | K18: =J18 -> 8900 | L18: =K18 -> 8900 | M18: =L18 -> 8900 | N18: =M18 -> 8900 | ... U18: =T18 -> 8900
B20: Sub-total for Operating costs | F20: =SUM(F13:F19) -> 104900 | G20: =SUM(G13:G19) -> 104900 | H20: =SUM(H13:H19) -> 104900 | I20: =SUM(I13:I19) -> 104900 | J20: =SUM(J13:J19) -> 104900 | K20: =SUM(K13:K19) -> 104900 | L20: =SUM(L13:L19) -> 104900 | M20: =SUM(M13:M19) -> 104900 | ... U20: =SUM(U13:U19) -> 104900
B22: Fixed costs
B23: Depreciation | C23: G$/annum | D23: 1 | E23: =E9/15 -> 26666.667 | F23: =D23*E23 -> 26666.667 | H23: =D23*E23 -> 26666.667 | I23: =H23 -> 26666.667 | J23: =I23 -> 26666.667 | K23: =J23 -> 26666.667 | L23: =K23 -> 26666.667 | M23: =L23 -> 26666.667 | N23: =M23 -> 26666.667 | O23: =N23 -> 26666.667 | P23: =O23 -> 26666.667 | ... U23: =T23 -> 26666.667 | V23: =SUM(H23:U23) -> 373333.33
B24: Land Rent | C24: Lumpsum | E24: 10000 | F24: =E24 -> 10000 | G24: =F24 -> 10000 | H24: =G24 -> 10000 | I24: =H24 -> 10000 | J24: =I24 -> 10000 | K24: =J24 -> 10000 | L24: =K24 -> 10000 | M24: =L24 -> 10000 | ... U24: =T24 -> 10000
