Workbook

Sheet Summary
A2: Investments | B2: Actual Investment ('000 KGS) | C2: ENPV ('000 KGS) | D2: EIRR (%) | E2: FNPV ('000 KGS) | F2: FIRR (%)
A3: A. Total investment in various activity (Additional financing)
A4: Roof and Ceilling insulation | B4: =('Roof and Ceilling insulation'!F12+'Roof and Ceilling insulation'!F16)/1000 -> 1045 | C4: ='Roof and Ceilling insulation'!G59/1000 -> 353.11374 | D4: ='Roof and Ceilling insulation'!G58 -> 0.15578105 | E4: ='Roof and Ceilling insulation'!G26/1000 -> 282.10563 | F4: ='Roof and Ceilling insulation'!G25 -> 0.21885915 | K4: Total financing= US$ 11million | L4: 9000000
A5: wall insulation | B5: =('Wall insulation'!F12+'Wall insulation'!F23)/1000 -> 1210 | C5: ='Wall insulation'!G72/1000 -> 831.05171 | D5: ='Efficient Windows (Double Tripl'!G69 -> 0.16945185 | E5: ='Wall insulation'!G33/1000 -> 982.04628 | F5: ='Wall insulation'!G32 -> 0.24516553 | K5: Total(KSM; Kyrgyztani SOM) | L5: =L4*87 -> 783000000
A6: Efficient windows (double tripple glazing) | B6: =('Efficient Windows (Double Tripl'!H12+'Efficient Windows (Double Tripl'!H20)/1000 -> 4730 | C6: ='Efficient Windows (Double Tripl'!G70/1000 -> 2595.2071 | D6: ='Wall insulation'!G71 -> 0.21759986 | E6: ='Efficient Windows (Double Tripl'!G70/1000 -> 2595.2071 | F6: ='Efficient Windows (Double Tripl'!G29 -> 0.10640257
A7: Efficient heating system | B7: =('Efficient heating systems'!G13+'Efficient heating systems'!G23)/1000 -> 280 | C7: ='Efficient heating systems'!G65/1000 -> 225.51345 | D7: ='Efficient heating systems'!G64 -> 0.18083253 | E7: ='Efficient heating systems'!G32/1000 -> 496.67285 | F7: ='Efficient heating systems'!G31 -> 0.38791303 | K7: Roof and Ceilling insulation | L7: =L5*0.3 -> 234900000 | M7: 0.3
A8: Air sealing/draft proofing | B8: =('Air Sealing Draft Proofing'!F13+'Air Sealing Draft Proofing'!F23)/1000 -> 330 | C8: ='Air Sealing Draft Proofing'!G67/1000 -> 171.73268 | D8: ='Air Sealing Draft Proofing'!G66 -> 0.2564628 | E8: =-('Air Sealing Draft Proofing'!G33)/1000 -> 257.38215 | F8: ='Air Sealing Draft Proofing'!G32 -> 0.38269858 | K8: wall insulation | L8: =L5*0.25 -> 195750000 | M8: 0.25
K9: Efficient windows (double tripple glazing) | L9: =L5*0.1 -> 78300000 | M9: 0.1
K10: Efficient heating system | L10: =L5*0.25 -> 195750000 | M10: 0.25
A11: Total 1 unit investment cost | B11: =SUM(B4:B8)*1000 -> 7595000 | C11: =(SUM(C4:C8)/SUM(B4:B8))*B11 -> 4176618.7 | D11: =(D4*B4+D5*B5+D6*B6+D7*B7)/(SUM(B4:B8)) -> 0.19061335 | E11: =(SUM(E4:E8)/SUM(B4:B8))*B11 -> 4613414 | F11: =(F4*B4+F5*B5+F6*B6+F7*B7)/SUM(B4:B8) -> 0.14973771 | K11: Air sealing/draft proofing | L11: =L5*0.1 -> 78300000 | M11: 0.1
B21: =SUM(B4:B10) -> 7595
A23: =
A25: Investments | B25: Actual Investment (USD) | C25: ENPV (USD) | D25: EIRR (%) | E25: FNPV (USD) | F25: FIRR (%)
A26: Roof and Ceiling Insulation | B26: 12011 | C26: 4057 | D26: 0.16 | E26: 3241 | F26: 0.22
A27: Wall Insulation | B27: 13908 | C27: 9552 | D27: 0.17 | E27: 11287 | F27: 0.25
A28: Efficient Windows (Double/Triple Glazing) | B28: 54368 | C28: 29839 | D28: 0.22 | E28: 29839 | F28: 0.11
A29: Efficient Heating System | B29: 3218 | C29: 2598 | D29: 0.18 | E29: 5713 | F29: 0.39
A30: Air Sealing / Draft Proofing | B30: 3793 | C30: 1977 | D30: 0.26 | E30: 2954 | F30: 0.38
A32: Total 1 Unit Investment Cost | B32: 87299 | C32: 48007 | D32: 0.19 | E32: 53028 | F32: 0.15

Sheet prices and other data
C3: Variable | D3: Kyrgyzstan (Recent / Suggested Value)
C4: Total export f.o.b | D4: ~US$4.3 billion | E4: 1989.77
C5: Total import c.i.f | D5: ~US$12.0 billion | E5: 3522.2
C6: Export duties | D6: Very limited / minimal
C7: Import duties | D7: ~5–10%
C8: VAT on imports | D8: 0.12
C9: Excise duties on imports | D9: Product specific
C10: Conversion factor | D10: 0.9 | M10: Variable | N10: Recent/Typical Value for Kyrgyzstan | O10: Notes / Suggested Use in EFA
C11: VAT Tax rate (fixed for last 5 years) | D11: 0.12 | M11: Total exports (f.o.b.) | N11: ~US$4.3 billion | O11: WITS/World Bank merchandise exports
C12: Official Exchange Rate (2022) | D12: ~87 KGS/USD | M12: Total imports (c.i.f.) | N12: ~US$12.0 billion | O12: WITS/World Bank merchandise imports
M13: Export duties | N13: Very limited | O13: Kyrgyzstan relies more on VAT/import-related taxation
C14: VAT Tax rate (fixed for last 5 Years) | D14: 0.14 | M14: Import duties | N14: Typically 5–10% | O14: Depends on EEU/customs classification
M15: VAT on imports | N15: 12% VAT | O15: Standard VAT applied to imports and domestic goods
C16: Official Exchange Rate (2022) | D16: 87 | M16: Excise duties on imports | N16: Product specific | O16: Tobacco, alcohol, fuel, luxury goods, vehicles
M17: Conversion factor | N17: 0.90–0.95 | O17: Often used in EFA for tradable/non-tradable adjustments
M18: VAT tax rate | N18: 0.12 | O18: Standard VAT rate in recent years
M19: Official exchange rate | N19: ~87 KGS/USD | O19: Kyrgyz Som exchange rate approximation
M20: Currency | N20: Kyrgyzstani Som (KGS) | O20: National currency
M21: Interest rate / discount rate for NPV | N21: 10%–12% | O21: WB economic analysis often uses 6–12%; financial analysis may use local borrowing cost
C22: BASIC DATA | M22: Wage of labor – Family labor | N22: Shadow wage | O22: Frequently adjusted downward in economic analysis
C23: Currency | D23: KGS | M23: Wage of labor – Hired labor | N23: Market wage | O23: Use local construction/heating retrofit labor rates
C24: Exchange rate | D24: 1 | E24: USD = | F24: 87 | G24: KZS
C25: Interest rate (NPV) | D25: 0.14 | E25: 14%
C27: Type of Labor | D27: Unit | E27: Wage KGS (Financial) | F27: Wage KGS (Economic) | G27: FC
C28: Family | D28: day | E28: 1200 | F28: 1000 | G28: 0.83
C29: Hired | D29: day | E29: 1800 | F29: 1800 | G29: 1
C36: Item | D36: Meaning
C37: Financial wage | D37: Actual market wage paid
C38: Economic wage | D38: Shadow-adjusted labor cost
C39: FC | D39: Conversion factor
C42: Why Family Labor FC < 1 In WB economic analysis: family/unskilled labor is often shadow-priced lower, especially in low-income or underemployed contexts. So: FC= Financial Economic ​ For family labor: 1000/1200≈0.83 For hired labor: 1800/1800=1 This is a reasonable simplified assumption for Kyrgyz EFA modeling.

Sheet Roof and Ceilling insulation
B1: FINANCIAL
C2: Unit | D2: Quantity | E2: Price | F2: Amount | G2: Year
B3: REVENUE | G3: 1 | H3: =G3+1 -> 2 | I3: =H3+1 -> 3 | J3: =I3+1 -> 4 | K3: =J3+1 -> 5 | L3: =K3+1 -> 6 | M3: =L3+1 -> 7 | N3: =M3+1 -> 8 | O3: =N3+1 -> 9 | P3: =O3+1 -> 10 | Q3: 11 | R3: 12 | S3: 13 | T3: 14 | U3: 15
B4: Heating 'Energy saved | C4: KWH /year | D4: 100000 | E4: 2.6 | F4: =D4*E4 -> 260000 | G4: =F4*0.5 -> 130000 | H4: =F4 -> 260000 | I4: =F4 -> 260000 | J4: =F4 -> 260000 | K4: =J4 -> 260000 | L4: =K4 -> 260000 | M4: =L4 -> 260000 | N4: =M4 -> 260000 | O4: =N4 -> 260000 | P4: =O4 -> 260000 | Q4: =P4 -> 260000 | R4: =Q4 -> 260000 | ... U4: =T4 -> 260000
B6: Sub-total Revenue | F6: =SUM(F4:F5) -> 260000 | G6: =SUM(G4:G5) -> 130000 | H6: =SUM(H4:H5) -> 260000 | I6: =SUM(I4:I5) -> 260000 | J6: =SUM(J4:J5) -> 260000 | K6: =SUM(K4:K5) -> 260000 | L6: =SUM(L4:L5) -> 260000 | M6: =SUM(M4:M5) -> 260000 | ... U6: =SUM(U4:U5) -> 260000
B8: CAPEX | F8: =E8*D8 -> 0 | G8: =F8 -> 0 | H8: =G8 -> 0
B9: Trasport/contingency | C9: Lumpsum | D9: 10 | E9: 20000 | F9: =E9*D9 -> 200000 | G9: =F9 -> 200000 | H9: =G9 -> 200000
B10: Roof ceiling insulation materials | C10: lumpsum | D10: 10 | E10: 90000 | F10: =E10*D10 -> 900000 | G10: =F10 -> 900000 | H10: =G10 -> 900000 | I10: 0 | J10: 0 | L10: =G10 -> 900000 | O10: =L10 -> 900000 | P10: =K10 -> 0 | T10: =O10 -> 900000
B11: Labor and installation | C11: lumpsum | D11: 1 | E11: 50000 | F11: =D11*E11 -> 50000 | G11: =D11*E11 -> 50000 | H11: =G11 -> 50000 | I11: 0 | J11: 0 | K11: 0
B12: Sub-total Investment | F12: =SUM(F10:F11) -> 950000 | G12: =SUM(G10:G11) -> 950000 | H12: =SUM(H10:H11) -> 950000 | I12: =SUM(I10:I11) -> 0 | J12: =SUM(J10:J11) -> 0 | K12: =SUM(K10:K11) -> 0 | M12: =SUM(M10:M11) -> 0 | N12: =SUM(N10:N11) -> 0 | P12: =SUM(P10:P11) -> 0 | R12: =SUM(R10:R11) -> 0 | S12: =SUM(S10:S11) -> 0 | T12: =SUM(T10:T11) -> 900000 | U12: =SUM(U10:U11) -> 0
F13: =D13*E13 -> 0
B14: OPEX – Roof and Ceilling insulation | F14: =D14*E14 -> 0
B15: OPEX | C15: KGS | E15: =F12*0.1 -> 95000 | F15: =E15 -> 95000 | G15: =F15 -> 95000 | H15: =F15 -> 95000 | I15: =H15 -> 95000 | J15: =I15 -> 95000 | K15: =J15 -> 95000 | L15: =K15 -> 95000 | M15: =L15 -> 95000 | N15: =M15 -> 95000 | O15: =N15 -> 95000 | P15: =O15 -> 95000 | ... U15: =T15 -> 95000
B16: Sub-total for Operating costs | F16: =F15 -> 95000 | G16: =SUM(G15:G15) -> 95000 | H16: =SUM(H15:H15) -> 95000 | I16: =SUM(I15:I15) -> 95000 | J16: =SUM(J15:J15) -> 95000 | K16: =SUM(K15:K15) -> 95000 | L16: =SUM(L15:L15) -> 95000 | M16: =SUM(M15:M15) -> 95000 | N16: =SUM(N15:N15) -> 95000 | ... U16: =SUM(U15:U15) -> 95000
B18: Fixed costs
B19: Depreciation | C19: KGS/annum | D19: 1 | E19: =E11/12 -> 4166.6667 | F19: =D19*E19 -> 4166.6667 | G19: =F19 -> 4166.6667 | H19: =D19*E19 -> 4166.6667 | I19: =H19 -> 4166.6667 | J19: =I19 -> 4166.6667 | K19: =J19 -> 4166.6667 | L19: =K19 -> 4166.6667 | M19: =L19 -> 4166.6667 | N19: =M19 -> 4166.6667 | O19: =N19 -> 4166.6667 | P19: =O19 -> 4166.6667 | ... U19: =T19 -> 4166.6667 | V19: =SUM(H19:U19) -> 58333.333
B20: Sub-total for Fixed costs | F20: =SUM(F19:F19) -> 4166.6667 | G20: =SUM(G19:G19) -> 4166.6667 | H20: =SUM(H19:H19) -> 4166.6667 | I20: =SUM(I19:I19) -> 4166.6667 | J20: =SUM(J19:J19) -> 4166.6667 | K20: =SUM(K19:K19) -> 4166.6667 | L20: =SUM(L19:L19) -> 4166.6667 | M20: =SUM(M19:M19) -> 4166.6667 | ... U20: =SUM(U19:U19) -> 4166.6667
B21: TOTAL COSTS | F21: =F12+F16+F20 -> 1049166.7 | G21: =G12+G16+G20 -> 1049166.7 | H21: =H12+H16+H20 -> 1049166.7 | I21: =I12+I16+I20 -> 99166.667 | J21: =J12+J16+J20 -> 99166.667 | K21: =K12+K16+K20 -> 99166.667 | L21: =L12+L16+L20 -> 99166.667 | M21: =M12+M16+M20 -> 99166.667 | ... U21: =U12+U16+U20 -> 99166.667
B23: GROSS MARGIN | C23: KGS/annum | G23: =G6-G12-G16 -> -915000 | H23: =H6-H12-H16 -> -785000 | I23: =I6-I12-I16 -> 165000 | J23: =J6-J12-J16 -> 165000 | K23: =K6-K12-K16 -> 165000 | L23: =L6-L12-L16 -> 165000 | M23: =M6-M12-M16 -> 165000 | N23: =N6-N12-N16 -> 165000 | ... U23: =U6-U12-U16 -> 165000
B24: NET MARGIN BEFORE PROFIT TAX | C24: KGS/annum | G24: =G23-G20 -> -919166.67 | H24: =-(H23-H20) -> 789166.67 | I24: =-(I23-I20) -> -160833.33 | J24: =J23-J20 -> 160833.33 | K24: =K23-K20 -> 160833.33 | L24: =L23-L20 -> 160833.33 | M24: =M23-M20 -> 160833.33 | N24: =N23-N20 -> 160833.33 | O24: =O23-O20 -> 160833.33 | P24: =P23-P20 -> 160833.33 | Q24: =Q23-Q20 -> 160833.33 | ... U24: =U23-U20 -> 160833.33
B25: FIRR | G25: =IRR(G24:U24) -> 0.21885915
B26: FNPV | G26: =NPV(0.1,G24:U24) -> 282105.63
B34: ECONOMIC
C35: Unit | D35: Quantity | E35: Price | F35: Amount | G35: Year
B36: REVENUE | G36: 1 | H36: =G36+1 -> 2 | I36: =H36+1 -> 3 | J36: =I36+1 -> 4 | K36: =J36+1 -> 5 | L36: =K36+1 -> 6 | M36: =L36+1 -> 7 | N36: =M36+1 -> 8 | O36: =N36+1 -> 9 | P36: =O36+1 -> 10 | Q36: 11 | R36: 12 | S36: 13 | T36: 14 | U36: 15
B37: Improved thermal comfort | C37: KGS/year | D37: 10 | E37: 8000 | F37: =E37*D37 -> 80000 | G37: =F37 -> 80000 | H37: =G37 -> 80000 | I37: =H37 -> 80000 | J37: =I37 -> 80000 | K37: =J37 -> 80000 | L37: =K37 -> 80000 | M37: =L37 -> 80000 | N37: =M37 -> 80000 | ... P37: =O37 -> 80000
B38: =B4 -> Heating 'Energy saved | C38: KWH/year | D38: =D4*1.1 -> 110000 | E38: =E4 -> 2.6 | F38: =D38*E38 -> 286000 | G38: =F38*0.5 -> 143000 | H38: =F38 -> 286000 | I38: =F38 -> 286000 | J38: =F38 -> 286000 | K38: =J38 -> 286000 | L38: =K38 -> 286000 | M38: =L38 -> 286000 | N38: =M38 -> 286000 | O38: =N38 -> 286000 | P38: =O38 -> 286000 | Q38: =P38 -> 286000 | R38: =Q38 -> 286000 | ... U38: =T38 -> 286000
B39: Sub-total Revenue | D39: =D6 -> 0 | E39: =E6*0.9 -> 0 | F39: =SUM(F36:F38) -> 366000 | G39: =SUM(G36:G38) -> 223001 | H39: =SUM(H36:H38) -> 366002 | I39: =SUM(I36:I38) -> 366003 | J39: =SUM(J36:J38) -> 366004 | K39: =SUM(K36:K38) -> 366005 | L39: =SUM(L36:L38) -> 366006 | M39: =SUM(M36:M38) -> 366007 | ... P39: =SUM(P36:P38) -> 366010 | Q39: =SUM(Q38:Q38) -> 286000 | R39: =SUM(R38:R38) -> 286000 | S39: =SUM(S38:S38) -> 286000 | T39: =SUM(T38:T38) -> 286000 | U39: =SUM(U38:U38) -> 286000
D40: =D7 -> 0 | E40: =E7*0.9 -> 0
B41: CAPEX | E41: =E8*0.9 -> 0
B42: Trasport/contingency | C42: lumpsum | D42: =D9 -> 10 | E42: =E9*0.8 -> 16000 | F42: =E42 -> 16000 | G42: =F42 -> 16000
B43: installment cost | C43: lumpsum | D43: =D10 -> 10 | E43: =E10*0.8 -> 72000 | F43: =D43*E43 -> 720000 | G43: =D43*E43 -> 720000 | H43: 0 | I43: 0 | J43: 0 | P43: =K43 -> 0
B44: Other Fixed Cost | C44: lumpsum | D44: =D11 -> 1 | E44: =E11*0.6 -> 30000 | F44: =D44*E44 -> 30000 | G44: =D44*E44 -> 30000 | H44: 0 | I44: 0 | J44: 0 | K44: 0
B45: Sub-total Investment | D45: =D12 -> 0 | E45: =E12*0.9 -> 0 | F45: =SUM(F43:F44) -> 750000 | G45: =SUM(G43:G44) -> 750000 | H45: =SUM(H43:H44) -> 0 | I45: =SUM(I43:I44) -> 0 | J45: =SUM(J43:J44) -> 0 | K45: =SUM(K43:K44) -> 0 | L45: =SUM(L43:L44) -> 0 | M45: =SUM(M43:M44) -> 0 | ... U45: =SUM(U43:U44) -> 0
D46: =D13 -> 0 | E46: =E13*0.9 -> 0 | F46: =D46*E46 -> 0
B47: OPEX | D47: =D14 -> 0 | E47: =E14*0.9 -> 0 | F47: =D47*E47 -> 0
B48: OPEX | C48: KGS | D48: =D15 -> 0 | E48: =F45*0.1 -> 75000 | F48: =E48 -> 75000 | G48: =F48 -> 75000 | H48: =F48 -> 75000 | I48: =H48 -> 75000 | J48: =I48 -> 75000 | K48: =J48 -> 75000 | L48: =K48 -> 75000 | M48: =L48 -> 75000 | N48: =M48 -> 75000 | O48: =N48 -> 75000 | P48: =O48 -> 75000 | ... U48: =T48 -> 75000
B49: Sub-total for Operating costs | D49: =D16 -> 0 | F49: =SUM(F48:F48) -> 75000 | G49: =SUM(G48:G48) -> 75000 | H49: =SUM(H48:H48) -> 75000 | I49: =SUM(I48:I48) -> 75000 | J49: =SUM(J48:J48) -> 75000 | K49: =SUM(K48:K48) -> 75000 | L49: =SUM(L48:L48) -> 75000 | M49: =SUM(M48:M48) -> 75000 | ... U49: =SUM(U48:U48) -> 75000
D50: =D17 -> 0
B51: Fixed costs | D51: =D18 -> 0
...

Sheet Wall insulation
B1: FINANCIAL
C2: Unit | D2: Quantity | E2: Price (KGS) | F2: Amount | G2: Year
B3: REVENUE | G3: 1 | H3: =G3+1 -> 2 | I3: =H3+1 -> 3 | J3: =I3+1 -> 4 | K3: =J3+1 -> 5 | L3: =K3+1 -> 6 | M3: =L3+1 -> 7 | N3: =M3+1 -> 8 | O3: =N3+1 -> 9 | P3: =O3+1 -> 10 | Q3: 11 | R3: 12 | S3: 13 | T3: 14 | U3: 15
B4: Heating Enegy saved | C4: KWH | D4: 15000 | E4: 3 | F4: =D4*E4*10 -> 450000 | H4: =F4 -> 450000 | I4: =F4 -> 450000 | J4: =F4 -> 450000 | K4: =J4 -> 450000 | L4: =K4 -> 450000 | M4: =L4 -> 450000 | N4: =M4 -> 450000 | O4: =N4 -> 450000 | P4: =O4 -> 450000 | Q4: =P4 -> 450000 | R4: =Q4 -> 450000 | ... U4: =T4 -> 450000
B5: Improved thermal comfort / productivity | C5: KGS/household/Year | D5: 8000 | E5: 3 | F5: =D5*E5 -> 24000 | H5: =F5 -> 24000 | I5: =H5 -> 24000 | J5: =H5 -> 24000 | K5: =J5 -> 24000 | L5: =K5 -> 24000 | M5: =L5 -> 24000 | N5: =M5 -> 24000 | O5: =N5 -> 24000 | P5: =O5 -> 24000 | Q5: =P5 -> 24000 | R5: =Q5 -> 24000 | ... U5: =T5 -> 24000
B6: Sub-total Revenue | F6: =SUM(F4:F5) -> 474000 | G6: =SUM(G4:G5) -> 0 | H6: =SUM(H4:H5) -> 474000 | I6: =SUM(I4:I5) -> 474000 | J6: =SUM(J4:J5) -> 474000 | K6: =SUM(K4:K5) -> 474000 | L6: =SUM(L4:L5) -> 474000 | M6: =SUM(M4:M5) -> 474000 | ... U6: =SUM(U4:U5) -> 474000
B8: COSTS
B9: Investment Costs
B10: Fixed Capital | C10: lumpsum | D10: 1 | E10: 800000 | F10: =D10*E10 -> 800000 | G10: =D10*E10 -> 800000 | H10: 0 | I10: 0 | J10: 0 | P10: =K10 -> 0
B11: Initial working cost | C11: lumpsum | D11: 1 | E11: 300000 | F11: =D11*E11 -> 300000 | G11: =D11*E11 -> 300000 | H11: 0 | I11: 0 | J11: 0 | K11: 0
B12: Sub-total Investment | F12: =SUM(F10:F11) -> 1100000 | G12: =SUM(G10:G11) -> 1100000 | H12: =SUM(H10:H11) -> 0 | I12: =SUM(I10:I11) -> 0 | J12: =SUM(J10:J11) -> 0 | K12: =SUM(K10:K11) -> 0 | L12: =SUM(L10:L11) -> 0 | M12: =SUM(M10:M11) -> 0 | ... U12: =SUM(U10:U11) -> 0
F13: =D13*E13 -> 0
B14: opex | F14: =D14*E14 -> 0
B15: Wages and Labor/maintenance, material replacements, repair | C15: KGS | F15: =F12*0.1 -> 110000 | G15: =F15*0.5 -> 55000 | H15: =F15 -> 110000 | I15: =H15 -> 110000 | J15: =I15 -> 110000 | K15: =J15 -> 110000 | L15: =K15 -> 110000 | M15: =L15 -> 110000 | N15: =M15 -> 110000 | O15: =N15 -> 110000 | P15: =O15 -> 110000 | ... U15: =T15 -> 110000
F16: 0 | H16: =F16 -> 0 | I16: =H16 -> 0 | J16: =I16 -> 0 | K16: =J16 -> 0 | L16: =K16 -> 0 | M16: =L16 -> 0 | N16: =M16 -> 0 | O16: =N16 -> 0 | P16: =O16 -> 0 | ... U16: =T16 -> 0
F17: 0 | G17: =F17*0.75 -> 0 | H17: =F17 -> 0 | I17: =H17 -> 0 | J17: =I17 -> 0 | K17: =J17 -> 0 | L17: =K17 -> 0 | M17: =L17 -> 0 | N17: =M17 -> 0 | O17: =N17 -> 0 | P17: =O17 -> 0 | ... U17: =T17 -> 0
F18: 0 | G18: =F18 -> 0 | H18: =G18 -> 0 | I18: =H18 -> 0 | J18: =I18 -> 0 | K18: =J18 -> 0 | L18: =K18 -> 0 | M18: =L18 -> 0 | N18: =M18 -> 0 | ... U18: =T18 -> 0
F20: 0 | G20: =F20 -> 0 | H20: =F20 -> 0 | I20: =H20 -> 0 | J20: =I20 -> 0 | K20: =J20 -> 0 | L20: =K20 -> 0 | M20: =L20 -> 0 | N20: =M20 -> 0 | O20: =N20 -> 0 | P20: =O20 -> 0 | ... U20: =T20 -> 0
F21: 0 | G21: =F21 -> 0 | H21: =G21 -> 0 | I21: =H21 -> 0 | J21: =I21 -> 0 | K21: =J21 -> 0 | L21: =K21 -> 0 | M21: =L21 -> 0 | N21: =M21 -> 0 | ... U21: =T21 -> 0
B23: Sub-total for Operating costs | F23: =SUM(F15:F22) -> 110000 | G23: =SUM(G15:G22) -> 55000 | H23: =SUM(H15:H22) -> 110000 | I23: =SUM(I15:I22) -> 110000 | J23: =SUM(J15:J22) -> 110000 | K23: =SUM(K15:K22) -> 110000 | L23: =SUM(L15:L22) -> 110000 | M23: =SUM(M15:M22) -> 110000 | ... U23: =SUM(U15:U22) -> 110000
B25: Fixed costs
B26: Depreciation | C26: KGS/annum | D26: 1 | E26: =E10/15 -> 53333.333 | F26: =D26*E26 -> 53333.333 | G26: =F26 -> 53333.333 | H26: =D26*E26 -> 53333.333 | I26: =H26 -> 53333.333 | J26: =I26 -> 53333.333 | K26: =J26 -> 53333.333 | L26: =K26 -> 53333.333 | M26: =L26 -> 53333.333 | N26: =M26 -> 53333.333 | O26: =N26 -> 53333.333 | P26: =O26 -> 53333.333 | ... U26: =T26 -> 53333.333 | V26: =SUM(H26:U26) -> 746666.67
B27: Sub-total for Fixed costs | F27: =SUM(F26:F26) -> 53333.333 | G27: =SUM(G26:G26) -> 53333.333 | H27: =SUM(H26:H26) -> 53333.333 | I27: =SUM(I26:I26) -> 53333.333 | J27: =SUM(J26:J26) -> 53333.333 | K27: =SUM(K26:K26) -> 53333.333 | L27: =SUM(L26:L26) -> 53333.333 | M27: =SUM(M26:M26) -> 53333.333 | ... U27: =SUM(U26:U26) -> 53333.333
B28: TOTAL COSTS | F28: =F12+F23+F27 -> 1263333.3 | G28: =G12+G23+G27 -> 1208333.3 | H28: =H12+H23+H27 -> 163333.33 | I28: =I12+I23+I27 -> 163333.33 | J28: =J12+J23+J27 -> 163333.33 | K28: =K12+K23+K27 -> 163333.33 | L28: =L12+L23+L27 -> 163333.33 | M28: =M12+M23+M27 -> 163333.33 | ... U28: =U12+U23+U27 -> 163333.33
B30: GROSS MARGIN | C30: KGS/annum | G30: =G6-G12-G23 -> -1155000 | H30: =H6-H12-H23 -> 364000 | I30: =I6-I12-I23 -> 364000 | J30: =J6-J12-J23 -> 364000 | K30: =K6-K12-K23 -> 364000 | L30: =L6-L12-L23 -> 364000 | M30: =M6-M12-M23 -> 364000 | N30: =N6-N12-N23 -> 364000 | ... U30: =U6-U12-U23 -> 364000
B31: NET MARGIN BEFORE PROFIT TAX | C31: KGS/annum | G31: =G30-G27 -> -1208333.3 | H31: =H30-H27 -> 310666.67 | I31: =I30-I27 -> 310666.67 | J31: =J30-J27 -> 310666.67 | K31: =K30-K27 -> 310666.67 | L31: =L30-L27 -> 310666.67 | M31: =M30-M27 -> 310666.67 | N31: =N30-N27 -> 310666.67 | ... U31: =U30-U27 -> 310666.67
B32: FIRR | G32: =IRR(G31:U31) -> 0.24516553
B33: FNPV | G33: =NPV(0.1,G31:U31) -> 982046.28
B41: ECONOMIC
C42: Unit | D42: Quantity | E42: Price | F42: Amount | G42: Year
B43: REVENUE | G43: 1 | H43: =G43+1 -> 2 | I43: =H43+1 -> 3 | J43: =I43+1 -> 4 | K43: =J43+1 -> 5 | L43: =K43+1 -> 6 | M43: =L43+1 -> 7 | N43: =M43+1 -> 8 | O43: =N43+1 -> 9 | P43: =O43+1 -> 10 | Q43: 11 | R43: 12 | S43: 13 | T43: 14 | U43: 15
B44: Enegy saved | C44: lumpsum | F44: =F4*0.9 -> 405000 | G44: =F44*0.5 -> 202500 | H44: =F44 -> 405000 | I44: =F44 -> 405000 | J44: =F44 -> 405000 | K44: =J44 -> 405000 | L44: =K44 -> 405000 | M44: =L44 -> 405000 | N44: =M44 -> 405000 | O44: =N44 -> 405000 | P44: =O44 -> 405000 | Q44: =P44 -> 405000 | R44: =Q44 -> 405000 | ... U44: =T44 -> 405000
B45: Productivity cost | C45: lumpsum | F45: =F5*0.9 -> 21600 | H45: =F45 -> 21600 | I45: =H45 -> 21600 | J45: =I45 -> 21600 | K45: =J45 -> 21600 | L45: =K45 -> 21600 | M45: =L45 -> 21600 | N45: =M45 -> 21600 | O45: =N45 -> 21600 | P45: =O45 -> 21600 | ... U45: =T45 -> 21600
B47: Sub-total Revenue | D47: =D6 -> 0 | E47: =E6*0.9 -> 0 | F47: =SUM(F44:F46) -> 426600 | G47: =SUM(G44:G46) -> 202500 | H47: =SUM(H44:H46) -> 426600 | I47: =SUM(I44:I46) -> 426600 | J47: =SUM(J44:J46) -> 426600 | K47: =SUM(K44:K46) -> 426600 | L47: =SUM(L44:L46) -> 426600 | M47: =SUM(M44:M46) -> 426600 | ... U47: =SUM(U44:U46) -> 426600
D48: =D7 -> 0 | E48: =E7*0.9 -> 0
B49: CAPEX | D49: =D8 -> 0 | E49: =E8*0.9 -> 0
B50: Investment Costs | D50: =D9 -> 0 | E50: =E9*0.9 -> 0
B51: Fixed Capital | C51: Nos. | D51: =D10 -> 1 | E51: =E10*0.9 -> 720000 | F51: =D51*E51 -> 720000 | G51: =D51*E51 -> 720000 | H51: 0 | I51: 0 | J51: 0 | P51: =K51 -> 0
B52: Installment | C52: lumpsum | D52: =D11 -> 1 | E52: =E11*0.9 -> 270000 | F52: =D52*E52 -> 270000 | G52: =D52*E52 -> 270000 | H52: 0 | I52: 0 | J52: 0 | K52: 0
B53: Sub-total Investment | D53: =D12 -> 0 | E53: =E12*0.9 -> 0 | F53: =SUM(F51:F52) -> 990000 | G53: =SUM(G51:G52) -> 990000 | H53: =SUM(H51:H52) -> 0 | I53: =SUM(I51:I52) -> 0 | J53: =SUM(J51:J52) -> 0 | K53: =SUM(K51:K52) -> 0 | L53: =SUM(L51:L52) -> 0 | M53: =SUM(M51:M52) -> 0 | ... U53: =SUM(U51:U52) -> 0
...

Sheet Efficient Windows (Double Tripl
B1: FINANCIAL
C2: Unit | D2: Quantity | E2: Price | F2: Amount | G2: Year
B3: REVENUE | D3: With Project | G3: 1 | H3: =G3+1 -> 2 | I3: =H3+1 -> 3 | J3: =I3+1 -> 4 | K3: =J3+1 -> 5 | L3: =K3+1 -> 6 | M3: =L3+1 -> 7 | N3: =M3+1 -> 8 | O3: =N3+1 -> 9 | P3: =O3+1 -> 10 | Q3: 11 | R3: 12 | S3: 13 | T3: 14 | U3: 15
B4: Energy saved | C4: KWH/hr | D4: 100000 | E4: 2.5 | H4: =I4 -> 250000 | I4: =J4 -> 250000 | J4: =D4*E4 -> 250000 | K4: =J4*1.2 -> 300000 | L4: =K4*1.2 -> 360000 | M4: =L4*1.2 -> 432000 | N4: =M4*1.2 -> 518400 | O4: =N4*1.2 -> 622080 | P4: =O4*1.2 -> 746496 | Q4: =P4*1.2 -> 895795.2 | R4: =Q4*1.2 -> 1074954.2 | ... U4: =T4*1.2 -> 1857520.9
B5: improved airflow | C5: kgs | D5: 5200 | E5: 3 | F5: =D5*E5 -> 15600 | G5: =F5 -> 15600 | H5: =F5 -> 15600 | I5: =H5 -> 15600 | J5: =I5 -> 15600 | K5: =J5 -> 15600 | L5: =K5 -> 15600 | M5: =L5 -> 15600 | N5: =M5 -> 15600 | O5: =N5 -> 15600 | P5: =O5 -> 15600 | ... U5: =T5 -> 15600
B6: Sub-total Revenue | F6: =SUM(F4:F5) -> 15600 | G6: =SUM(G4:G5) -> 15600 | H6: =SUM(H4:H5) -> 265600 | I6: =SUM(I4:I5) -> 265600 | J6: =SUM(J4:J5) -> 265600 | K6: =SUM(K4:K5) -> 315600 | L6: =SUM(L4:L5) -> 375600 | M6: =SUM(M4:M5) -> 447600 | ... U6: =SUM(U4:U5) -> 1873120.9
B8: CAPEX
B9: Investment Costs
B10: installation | C10: Nos. | D10: 10 | E10: 30000 | F10: =D10*E10 -> 300000 | G10: =F10 -> 300000 | H10: =G10 -> 300000 | I10: 0 | J10: 0 | K10: 0
B11: cost of capital | C11: lumpsum | D11: 1 | E11: 4000000 | F11: =D11*E11 -> 4000000 | G11: =F11 -> 4000000 | H11: =G11 -> 4000000 | I11: 0 | J11: 0 | K11: 0
B12: Sub-total Investment | F12: 0 | G12: 0 | H12: =SUM(H10:H11) -> 4300000 | I12: =SUM(I10:I11) -> 0 | J12: =SUM(J10:J11) -> 0 | K12: =SUM(K10:K11) -> 0
F13: =D13*E13 -> 0
B14: OPEX | F14: =D14*E14 -> 0
B15: Wages and Labor, maintenance, repair, etc | C15: KGS | D15: =H12*0.1 -> 430000 | E15: 1 | F15: =D15*E15 -> 430000 | G15: =F15 -> 430000 | H15: =F15 -> 430000 | I15: =H15 -> 430000 | J15: =I15 -> 430000 | K15: =J15 -> 430000 | L15: =K15 -> 430000 | M15: =L15 -> 430000 | N15: =M15 -> 430000 | O15: =N15 -> 430000 | P15: =O15 -> 430000 | ... T15: =S15 -> 430000 | U15: =T15*0.5 -> 215000
D16: 0 | E16: 0 | F16: =D16*E16 -> 0 | G16: =F16 -> 0 | H16: =F16 -> 0 | I16: =H16 -> 0 | J16: =H16 -> 0 | K16: =J16 -> 0 | L16: =J16 -> 0 | M16: =L16 -> 0 | N16: =L16 -> 0 | O16: =N16 -> 0 | P16: =N16 -> 0 | Q16: =P16 -> 0 | R16: =P16 -> 0 | S16: =R16 -> 0 | T16: =R16 -> 0 | U16: =T16 -> 0
F17: 0 | G17: =F17 -> 0 | H17: =F17 -> 0 | I17: =H17 -> 0 | J17: =I17 -> 0 | K17: =J17 -> 0 | L17: =K17 -> 0 | M17: =L17 -> 0 | N17: =M17 -> 0 | O17: =N17 -> 0 | P17: =O17 -> 0 | ... U17: =T17 -> 0
F18: 0 | G18: =F18 -> 0 | H18: =G18 -> 0 | I18: =H18 -> 0 | J18: =I18 -> 0 | K18: =J18 -> 0 | L18: =K18 -> 0 | M18: =L18 -> 0 | N18: =M18 -> 0 | ... U18: =T18 -> 0
F19: 0 | G19: =F19 -> 0 | H19: =F19 -> 0 | I19: =H19 -> 0 | J19: =I19 -> 0 | K19: =J19 -> 0 | L19: =K19 -> 0 | M19: =L19 -> 0 | N19: =M19 -> 0 | O19: =N19 -> 0 | P19: =O19 -> 0 | ... U19: =T19 -> 0
B20: Sub-total for Operating costs | F20: =SUM(F15:F19) -> 430000 | G20: =SUM(G15:G19) -> 430000 | H20: =SUM(H15:H19) -> 430000 | I20: =SUM(I15:I19) -> 430000 | J20: =SUM(J15:J19) -> 430000 | K20: =SUM(K15:K19) -> 430000 | L20: =SUM(L15:L19) -> 430000 | M20: =SUM(M15:M19) -> 430000 | ... U20: =SUM(U15:U19) -> 215000
B22: Fixed costs
B23: Depreciation | C23: KGS/annum | D23: 1 | E23: =E11/15 -> 266666.67 | F23: =D23*E23 -> 266666.67 | G23: =F23 -> 266666.67 | H23: =D23*E23 -> 266666.67 | I23: =H23 -> 266666.67 | J23: =I23 -> 266666.67 | K23: =J23 -> 266666.67 | L23: =K23 -> 266666.67 | M23: =L23 -> 266666.67 | N23: =M23 -> 266666.67 | O23: =N23 -> 266666.67 | P23: =O23 -> 266666.67 | ... U23: =T23 -> 266666.67 | V23: =SUM(H23:U23) -> 3733333.3
B24: Sub-total for Fixed costs | F24: =F15 -> 430000 | G24: =G15 -> 430000 | H24: =H15 -> 430000 | I24: =I15 -> 430000 | J24: =J15 -> 430000 | K24: =K15 -> 430000 | L24: =L15 -> 430000 | M24: =M15 -> 430000 | ... U24: =U15 -> 215000
B25: TOTAL COSTS | F25: =F12+F20+F24 -> 860000 | G25: =G12+G20+G24 -> 860000 | H25: =H12+H20+H24 -> 5160000 | I25: =I12+I20+I24 -> 860000 | J25: =J12+J20+J24 -> 860000 | K25: =K12+K20+K24 -> 860000 | L25: =L12+L20+L24 -> 860000 | M25: =M12+M20+M24 -> 860000 | ... U25: =U12+U20+U24 -> 430000
B27: GROSS MARGIN | C27: KGS/annum | I27: =-(I6-I12-I20) -> 164400 | J27: =J6-J12-J20 -> -164400 | K27: =K6-K12-K20 -> -114400 | L27: =L6-L12-L20 -> -54400 | M27: =M6-M12-M20 -> 17600 | N27: =N6-N12-N20 -> 104000 | O27: =O6-O12-O20 -> 207680 | P27: =P6-P12-P20 -> 332096 | Q27: =Q6-Q12-Q20 -> 481395.2 | ... U27: =U6-U12-U20 -> 1658120.9
B28: NET MARGIN | C28: KGS/annum | G28: =H28 -> 265600 | H28: =I28 -> 265600 | I28: =-(I27-I24) -> 265600 | J28: =I28 -> 265600 | K28: =K27-K24 -> -544400 | L28: =L27-L24 -> -484400 | M28: =(M27-M24) -> -412400 | N28: =N27-N24 -> -326000 | O28: =O27-O24 -> -222320 | P28: =P27-P24 -> -97904 | Q28: =Q27-Q24 -> 51395.2 | R28: =R27-R24 -> 230554.24 | S28: =S27-S24 -> 445545.09 | T28: =T27-T24 -> 703534.11 | U28: =U27-U24 -> 1443120.9
B29: FIRR | G29: =IRR(I28:U28) -> 0.10640257
B30: FNPV | G30: =-(NPV(0.1,G28:U28)) -> -485984.22
B41: ECONOMIC
C42: Unit | D42: Quantity | E42: Price | F42: Amount | G42: Year
B43: REVENUE | D43: With Project | G43: 1 | H43: =G43+1 -> 2 | I43: =H43+1 -> 3 | J43: =I43+1 -> 4 | K43: =J43+1 -> 5 | L43: =K43+1 -> 6 | M43: =L43+1 -> 7 | N43: =M43+1 -> 8 | O43: =N43+1 -> 9 | P43: =O43+1 -> 10 | Q43: 11 | R43: 12 | S43: 13 | T43: 14 | U43: 15
B44: Energy saved | C44: KWH/h | D44: =D4 -> 100000 | E44: =E4*0.9 -> 2.25 | G44: 0 | H44: =F44 -> 0 | I44: =D44*E44*10 -> 2250000 | J44: =I44 -> 2250000 | K44: =J44 -> 2250000 | L44: =K44 -> 2250000 | M44: =L44 -> 2250000 | N44: =M44 -> 2250000 | O44: =N44 -> 2250000 | P44: =O44 -> 2250000 | Q44: =P44 -> 2250000 | ... U44: =T44 -> 2250000
B45: Improved airflow | C45: No | D45: =D5 -> 5200 | E45: =E5*0.9 -> 2.7 | G45: =F45 -> 0 | H45: =F45 -> 0 | I45: =E45*D45 -> 14040 | J45: =I45 -> 14040 | K45: =J45 -> 14040 | L45: =K45 -> 14040 | M45: =L45 -> 14040 | N45: =M45 -> 14040 | O45: =N45 -> 14040 | P45: =O45 -> 14040 | Q45: =P45 -> 14040 | ... U45: =T45 -> 14040
B46: Sub-total Revenue | F46: =SUM(F44:F45) -> 0 | G46: =SUM(G44:G45) -> 0 | H46: =SUM(H44:H45) -> 0 | I46: =SUM(I44:I45) -> 2264040 | J46: =SUM(J44:J45) -> 2264040 | K46: =SUM(K44:K45) -> 2264040 | L46: =SUM(L44:L45) -> 2264040 | M46: =SUM(M44:M45) -> 2264040 | ... U46: =SUM(U44:U45) -> 2264040
B48: CAPEX
B49: Investment Costs
B50: Capital Investment | C50: Nos. | D50: =D10 -> 10 | E50: =E10*0.9 -> 27000 | F50: =D50*E50 -> 270000 | G50: =D50*E50 -> 270000 | H50: =G50 -> 270000 | I50: 0 | J50: 0 | K50: 0
B51: Intallation cost | C51: lumpsum | D51: 1 | E51: =E11*0.9 -> 3600000 | F51: =D51*E51 -> 3600000 | G51: =D51*E51 -> 3600000 | H51: =G51 -> 3600000 | I51: 0 | J51: 0 | K51: 0
B52: Sub-total Investment | F52: =SUM(F50:F51) -> 3870000 | G52: =SUM(G50:G51) -> 3870000 | H52: =SUM(H50:H51) -> 3870000 | I52: =SUM(I50:I51) -> 0 | J52: =SUM(J50:J51) -> 0 | K52: =SUM(K50:K51) -> 0
F53: =D53*E53 -> 0
B54: OPEX | F54: =D54*E54 -> 0
...

Sheet Efficient heating systems
B1: FINANCIAL
C2: Unit | D2: Quantity | E2: Price | F2: Amount | G2: Year
B3: REVENUE | G3: 1 | H3: =G3+1 -> 2 | I3: =H3+1 -> 3 | J3: =I3+1 -> 4 | K3: =J3+1 -> 5 | L3: =K3+1 -> 6 | M3: =L3+1 -> 7 | N3: =M3+1 -> 8 | O3: =N3+1 -> 9 | P3: =O3+1 -> 10 | Q3: 11 | R3: 12 | S3: 13 | T3: 14 | U3: 15
B4: Electricity /heating energy saved | C4: KWH/h | D4: 40000 | E4: 3 | F4: =D4*E4 -> 120000 | H4: =F4 -> 120000 | I4: =F4 -> 120000 | J4: =F4 -> 120000 | K4: =J4 -> 120000 | L4: =K4 -> 120000 | M4: =L4 -> 120000 | N4: =M4 -> 120000 | O4: =N4 -> 120000 | P4: =O4 -> 120000 | Q4: =P4 -> 120000 | R4: =Q4 -> 120000 | ... U4: =T4 -> 120000
B5: productivity | C5: hr | D5: 5000 | E5: 10 | F5: =D5*E5 -> 50000 | G5: =F5 -> 50000 | H5: =D5*E5 -> 50000 | I5: =D5*E5 -> 50000 | J5: =D5*E5 -> 50000 | K5: =J5 -> 50000 | L5: =K5 -> 50000 | M5: =L5 -> 50000 | N5: =M5 -> 50000 | O5: =N5 -> 50000 | P5: =O5 -> 50000 | Q5: =P5 -> 50000 | R5: =Q5 -> 50000 | ... U5: =T5 -> 50000
B6: others | C6: lumpsum | D6: 0 | E6: 0 | F6: =E6*D6 -> 0 | J6: =F6 -> 0 | K6: =J6 -> 0 | L6: =K6 -> 0 | M6: =L6 -> 0 | N6: =J6 -> 0 | O6: =K6 -> 0 | P6: =L6 -> 0 | Q6: =M6 -> 0 | R6: =N6 -> 0 | S6: =O6 -> 0 | T6: =P6 -> 0 | U6: =Q6 -> 0
B7: Sub-total Revenue | F7: =SUM(F4:F6) -> 170000 | G7: =SUM(G4:G6) -> 50000 | H7: =SUM(H4:H6) -> 170000 | I7: =SUM(I4:I6) -> 170000 | J7: =SUM(J4:J6) -> 170000 | K7: =SUM(K4:K6) -> 170000 | L7: =SUM(L4:L6) -> 170000 | M7: =SUM(M4:M6) -> 170000 | ... U7: =SUM(U4:U6) -> 170000
B9: CAPEX
B10: Investment Costs
B11: Fixed Cost | C11: lumpsum | D11: 1 | E11: 200000 | F11: =D11*E11 -> 200000 | G11: =D11*E11 -> 200000 | H11: 0 | I11: 0 | J11: 0 | P11: =K11 -> 0
B12: Installment | C12: lumpsum | D12: 10 | E12: 8000 | F12: =D12*E12 -> 80000 | G12: =D12*E12 -> 80000 | H12: 0 | I12: 0 | J12: 0 | K12: 0
B13: Sub-total Investment | F13: =SUM(F11:F12) -> 280000 | G13: =SUM(G11:G12) -> 280000 | H13: =SUM(H11:H12) -> 0 | I13: =SUM(I11:I12) -> 0 | J13: =SUM(J11:J12) -> 0 | K13: =SUM(K11:K12) -> 0 | L13: =SUM(L11:L12) -> 0 | M13: =SUM(M11:M12) -> 0 | ... U13: =SUM(U11:U12) -> 0
F14: =D14*E14 -> 0
B15: OPEX | F15: =D15*E15 -> 0
B16: wages and Labor; maintenance, repair , cleaning | C16: KGS | D16: 2 | E16: =F13*0.1 -> 28000 | F16: =D16*E16 -> 56000 | G16: =F16 -> 56000 | H16: =F16 -> 56000 | I16: =H16 -> 56000 | J16: =I16 -> 56000 | K16: =J16 -> 56000 | L16: =K16 -> 56000 | M16: =L16 -> 56000 | N16: =M16 -> 56000 | O16: =N16 -> 56000 | P16: =O16 -> 56000 | ... U16: =T16 -> 56000
D17: 0 | E17: 0 | F17: =15*E17 -> 0 | G17: =F17 -> 0 | H17: =F17 -> 0 | I17: =H17 -> 0 | J17: =I17 -> 0 | K17: =J17 -> 0 | L17: =K17 -> 0 | M17: =L17 -> 0 | N17: =M17 -> 0 | O17: =N17 -> 0 | P17: =O17 -> 0 | ... U17: =T17 -> 0
E18: 0 | F18: 3000 | G18: =F18 -> 3000 | H18: =D18*E18*1 -> 0 | I18: =D18*E18*1 -> 0 | J18: =D18*E18 -> 0 | K18: =J18 -> 0 | L18: =K18 -> 0 | M18: =L18 -> 0 | N18: =M18 -> 0 | O18: =N18 -> 0 | P18: =O18 -> 0 | Q18: =P18 -> 0 | R18: =Q18 -> 0 | ... U18: =T18 -> 0
E19: 0 | F19: =D19*E19 -> 0 | G19: =F19 -> 0 | H19: =F19 -> 0 | I19: =H19 -> 0 | J19: =I19 -> 0 | K19: =J19 -> 0 | L19: =K19 -> 0 | M19: =L19 -> 0 | N19: =M19 -> 0 | O19: =N19 -> 0 | P19: =O19 -> 0 | ... U19: =T19 -> 0
E20: 0 | F20: =D20*E20 -> 0 | G20: =F20 -> 0 | H20: =G20 -> 0 | I20: =H20 -> 0 | J20: =I20 -> 0 | K20: =J20 -> 0 | L20: =K20 -> 0 | M20: =L20 -> 0 | N20: =M20 -> 0 | ... U20: =T20 -> 0
E21: 0 | F21: =D21*E21 -> 0 | G21: =F21 -> 0 | H21: =F21 -> 0 | I21: =F21 -> 0 | J21: =F21 -> 0 | K21: =J21 -> 0 | L21: =K21 -> 0 | M21: =L21 -> 0 | N21: =M21 -> 0 | O21: =N21 -> 0 | P21: =O21 -> 0 | Q21: =P21 -> 0 | R21: =Q21 -> 0 | ... U21: =T21 -> 0
B22: Sub-total for Operating costs | F22: =SUM(F16:F21) -> 59000 | G22: =SUM(G16:G21) -> 59000 | H22: =SUM(H16:H21) -> 56000 | I22: =SUM(I16:I21) -> 56000 | J22: =SUM(J16:J21) -> 56000 | K22: =SUM(K16:K21) -> 56000 | L22: =SUM(L16:L21) -> 56000 | M22: =SUM(M16:M21) -> 56000 | ... U22: =SUM(U16:U21) -> 56000
B24: Fixed costs
B25: Depreciation | C25: KZS/annum | D25: 1 | E25: =E12/15 -> 533.33333 | F25: =D25*E25 -> 533.33333 | G25: =F25 -> 533.33333 | H25: =D25*E25 -> 533.33333 | I25: =H25 -> 533.33333 | J25: =I25 -> 533.33333 | K25: =J25 -> 533.33333 | L25: =K25 -> 533.33333 | M25: =L25 -> 533.33333 | N25: =M25 -> 533.33333 | O25: =N25 -> 533.33333 | P25: =O25 -> 533.33333 | ... U25: =T25 -> 533.33333 | V25: =SUM(H25:U25) -> 7466.6667
B26: Sub-total for Fixed costs | F26: =SUM(F25:F25) -> 533.33333 | G26: =SUM(G25:G25) -> 533.33333 | H26: =SUM(H25:H25) -> 533.33333 | I26: =SUM(I25:I25) -> 533.33333 | J26: =SUM(J25:J25) -> 533.33333 | K26: =SUM(K25:K25) -> 533.33333 | L26: =SUM(L25:L25) -> 533.33333 | M26: =SUM(M25:M25) -> 533.33333 | ... U26: =SUM(U25:U25) -> 533.33333
B27: TOTAL COSTS | F27: =F13+F22+F26 -> 339533.33 | G27: =G13+G22+G26 -> 339533.33 | H27: =H13+H22+H26 -> 56533.333 | I27: =I13+I22+I26 -> 56533.333 | J27: =J13+J22+J26 -> 56533.333 | K27: =K13+K22+K26 -> 56533.333 | L27: =L13+L22+L26 -> 56533.333 | M27: =M13+M22+M26 -> 56533.333 | ... U27: =U13+U22+U26 -> 56533.333
B29: GROSS MARGIN | C29: KZS/annum | G29: =G7-G13-G22 -> -289000 | H29: =H7-H13-H22 -> 114000 | I29: =I7-I13-I22 -> 114000 | J29: =J7-J13-J22 -> 114000 | K29: =K7-K13-K22 -> 114000 | L29: =L7-L13-L22 -> 114000 | M29: =M7-M13-M22 -> 114000 | N29: =N7-N13-N22 -> 114000 | ... U29: =U7-U13-U22 -> 114000
B30: NET MARGIN BEFORE PROFIT TAX | C30: KZS/annum | G30: =G29-G26 -> -289533.33 | H30: =H29-H26 -> 113466.67 | I30: =I29-I26 -> 113466.67 | J30: =J29-J26 -> 113466.67 | K30: =K29-K26 -> 113466.67 | L30: =L29-L26 -> 113466.67 | M30: =M29-M26 -> 113466.67 | N30: =N29-N26 -> 113466.67 | ... U30: =U29-U26 -> 113466.67
B31: FIRR | G31: =IRR(G30:U30) -> 0.38791303
B32: FNPV | G32: =NPV(0.1,G30:U30) -> 496672.85
B34: ECONOMIC
C35: Unit | D35: Quantity | E35: Price | F35: Amount | G35: Year
B36: REVENUE | G36: 1 | H36: =G36+1 -> 2 | I36: =H36+1 -> 3 | J36: =I36+1 -> 4 | K36: =J36+1 -> 5 | L36: =K36+1 -> 6 | M36: =L36+1 -> 7 | N36: =M36+1 -> 8 | O36: =N36+1 -> 9 | P36: =O36+1 -> 10 | Q36: 11 | R36: 12 | S36: 13 | T36: 14 | U36: 15
B37: Electricity saved | C37: KWH/h | D37: =D4*0.9 -> 36000 | E37: =E4*0.9 -> 2.7 | F37: =D37*E37 -> 97200 | H37: =F37 -> 97200 | I37: =F37 -> 97200 | J37: =F37 -> 97200 | K37: =J37 -> 97200 | L37: =K37 -> 97200 | M37: =L37 -> 97200 | N37: =M37 -> 97200 | O37: =N37 -> 97200 | P37: =O37 -> 97200 | Q37: =P37 -> 97200 | R37: =Q37 -> 97200 | ... U37: =T37 -> 97200
B38: productivity | C38: Hr | D38: =D5 -> 5000 | E38: =E5 -> 10 | F38: =D38*E38 -> 50000 | G38: =F38 -> 50000 | H38: =D38*E38 -> 50000 | I38: =D38*E38 -> 50000 | J38: =D38*E38 -> 50000 | K38: =J38 -> 50000 | L38: =K38 -> 50000 | M38: =L38 -> 50000 | N38: =M38 -> 50000 | O38: =N38 -> 50000 | P38: =O38 -> 50000 | Q38: =P38 -> 50000 | R38: =Q38 -> 50000 | ... U38: =T38 -> 50000
B39: others | C39: Nos. | D39: =D6 -> 0 | E39: =E6 -> 0 | F39: =D39*E39 -> 0 | G39: =F39 -> 0 | H39: =G39 -> 0 | I39: =H39 -> 0 | J39: =I39 -> 0 | K39: =J39 -> 0 | L39: =K39 -> 0 | M39: =L39 -> 0 | N39: =M39 -> 0 | ... P39: =O39 -> 0 | U39: =P39 -> 0
B40: Sub-total Revenue | D40: =D7 -> 0 | E40: =E7*0.9 -> 0 | F40: =SUM(F37:F39) -> 147200 | G40: =SUM(G37:G39) -> 50000 | H40: =SUM(H37:H39) -> 147200 | I40: =SUM(I37:I39) -> 147200 | J40: =SUM(J37:J39) -> 147200 | K40: =SUM(K37:K39) -> 147200 | L40: =SUM(L37:L39) -> 147200 | M40: =SUM(M37:M39) -> 147200 | ... U40: =SUM(U37:U39) -> 147200
D41: =D8 -> 0 | E41: =E8*0.9 -> 0
B42: CAPEX | D42: =D9 -> 0 | E42: =E9*0.9 -> 0
B43: Investment Costs | D43: =D10 -> 0 | E43: =E10*0.9 -> 0
B44: Fixed Cost | C44: Nos. | D44: =D11 -> 1 | E44: =E11*0.9 -> 180000 | F44: =D44*E44 -> 180000 | G44: =D44*E44 -> 180000 | H44: 0 | I44: 0 | J44: 0 | P44: =K44 -> 0
...

Sheet Air Sealing   Draft Proofing
B1: FINANCIAL
C2: Unit | D2: Quantity | E2: Price | F2: Amount | G2: Year
B3: REVENUE | G3: 1 | H3: =G3+1 -> 2 | I3: =H3+1 -> 3 | J3: =I3+1 -> 4 | K3: =J3+1 -> 5 | L3: =K3+1 -> 6 | M3: =L3+1 -> 7 | N3: =M3+1 -> 8 | O3: =N3+1 -> 9 | P3: =O3+1 -> 10 | Q3: 11 | R3: 12 | S3: 13 | T3: 14 | U3: 15
B4: Electricity saved | C4: KWH/h | D4: 80000 | E4: 2.5 | F4: 0 | G4: 0 | H4: =I4 -> 200000 | I4: =J4 -> 200000 | J4: =D4*E4 -> 200000 | K4: =J4 -> 200000 | L4: =K4 -> 200000 | M4: =L4 -> 200000 | N4: =M4 -> 200000 | O4: =N4 -> 200000 | P4: =O4 -> 200000 | Q4: =P4 -> 200000 | R4: =Q4 -> 200000 | ... U4: =T4 -> 200000
E5: 0 | F5: 0 | H5: =E5 -> 0 | I5: =E5 -> 0 | J5: =I5 -> 0 | K5: =J5 -> 0 | L5: =K5 -> 0 | M5: =L5 -> 0 | N5: =M5 -> 0 | O5: =N5 -> 0 | P5: =O5 -> 0 | Q5: =P5 -> 0 | ... U5: =T5 -> 0
K6: =J6 -> 0 | L6: =K6 -> 0 | M6: =L6 -> 0 | N6: =M6 -> 0 | O6: =N6 -> 0 | P6: =O6 -> 0 | Q6: =P6 -> 0 | R6: =Q6 -> 0 | ... U6: =T6 -> 0
G7: =F7 -> 0 | H7: =F7 -> 0 | I7: =G7 -> 0 | J7: =H7 -> 0 | K7: =J7 -> 0 | L7: =K7 -> 0 | M7: =L7 -> 0 | N7: =M7 -> 0 | O7: =N7 -> 0 | P7: =O7 -> 0 | Q7: =P7 -> 0 | R7: =Q7 -> 0 | ... U7: =T7 -> 0
B8: Sub-total Revenue | F8: =SUM(F4:F7) -> 0 | G8: =SUM(G4:G7) -> 0 | H8: =SUM(H4:H7) -> 200000 | I8: =SUM(I4:I7) -> 200000 | J8: =SUM(J4:J7) -> 200000 | K8: =SUM(K4:K7) -> 200000 | L8: =SUM(L4:L7) -> 200000 | M8: =SUM(M4:M7) -> 200000 | ... U8: =SUM(U4:U7) -> 200000
B10: CAPEX
B11: Investment Costs
B12: Fixed Capital,and other equipment | C12: lumpsum | D12: 10 | E12: 30000 | F12: =D12*E12 -> 300000 | G12: =D12*E12 -> 300000 | H12: =G12 -> 300000 | I12: 0 | L12: 10000 | O12: 10000 | R12: 10000 | U12: 10000
B13: Sub-total Investment | F13: =SUM(F12:F12) -> 300000 | G13: =SUM(G12:G12) -> 300000 | H13: =SUM(H12:H12) -> 300000 | I13: =SUM(I12:I12) -> 0 | J13: =SUM(J12:J12) -> 0 | K13: =SUM(K12:K12) -> 0 | L13: =SUM(L12:L12) -> 10000 | M13: =SUM(M12:M12) -> 0 | ... U13: =SUM(U12:U12) -> 10000
F14: =D14*E14 -> 0
B15: OPEX | F15: =D15*E15 -> 0
B16: wages and Labor, electricity expenses, maintenance | C16: kgm | D16: 10 | E16: 1000 | F16: =F13*0.1 -> 30000 | G16: =F16 -> 30000 | H16: =G16 -> 30000 | I16: =H16 -> 30000 | J16: =I16 -> 30000 | K16: =J16 -> 30000 | L16: =K16 -> 30000 | M16: =L16 -> 30000 | N16: =M16 -> 30000 | ... U16: =T16 -> 30000
D17: 200 | E17: 1500 | F17: 0 | G17: =F17 -> 0 | H17: =G17 -> 0 | I17: =H17 -> 0 | J17: =I17 -> 0 | K17: =J17 -> 0 | L17: =K17 -> 0 | M17: =L17 -> 0 | N17: =M17 -> 0 | ... U17: =T17 -> 0
F18: 0 | G18: =F18 -> 0 | H18: =G18 -> 0 | I18: =H18 -> 0 | J18: =J4*0.75 -> 150000 | K18: =J18 -> 150000 | L18: =K18 -> 150000 | M18: =L18 -> 150000 | N18: =M18 -> 150000 | O18: =N18 -> 150000 | P18: =O18 -> 150000 | Q18: =P18 -> 150000 | R18: =Q18 -> 150000 | ... U18: =T18 -> 150000
F19: 0 | G19: =F19 -> 0 | H19: =G19 -> 0 | I19: =H19 -> 0 | J19: 10000 | K19: =J19 -> 10000 | L19: =K19 -> 10000 | M19: =L19 -> 10000 | N19: =M19 -> 10000 | O19: =N19 -> 10000 | P19: =O19 -> 10000 | Q19: =P19 -> 10000 | R19: =Q19 -> 10000 | ... U19: =T19 -> 10000
F20: 0 | G20: =F20 -> 0 | H20: =G20 -> 0 | I20: =H20 -> 0 | J20: =I20 -> 0 | K20: =J20 -> 0 | L20: =K20 -> 0 | M20: =L20 -> 0 | N20: =M20 -> 0 | ... U20: =T20 -> 0
F21: 0 | G21: =F21 -> 0 | H21: =G21 -> 0 | I21: =H21 -> 0 | J21: =I21 -> 0 | K21: =J21 -> 0 | L21: =K21 -> 0 | M21: =L21 -> 0 | N21: =M21 -> 0 | ... U21: =T21 -> 0
B23: Sub-total for Operating costs | F23: =SUM(F16:F22) -> 30000 | G23: =SUM(G16:G22) -> 30000 | H23: =SUM(H16:H22) -> 30000 | I23: =SUM(I16:I22) -> 30000 | J23: =SUM(J16:J22) -> 190000 | K23: =SUM(K16:K22) -> 190000 | L23: =SUM(L16:L22) -> 190000 | M23: =SUM(M16:M22) -> 190000 | ... U23: =SUM(U16:U22) -> 190000
B25: Fixed costs
B26: Depreciation | C26: Kgs/anuum | D26: 1 | E26: =E12/15 -> 2000 | F26: =D26*E26 -> 2000 | H26: =D26*E26 -> 2000 | I26: =H26 -> 2000 | J26: =I26 -> 2000 | K26: =J26 -> 2000 | L26: =K26 -> 2000 | M26: =L26 -> 2000 | N26: =M26 -> 2000 | O26: =N26 -> 2000 | P26: =O26 -> 2000 | ... U26: =T26 -> 2000 | V26: =SUM(H26:U26) -> 28000
B27: Sub-total for Fixed costs | F27: =SUM(F26:F26) -> 2000 | G27: =SUM(G26:G26) -> 0 | H27: =SUM(H26:H26) -> 2000 | I27: =SUM(I26:I26) -> 2000 | J27: =SUM(J26:J26) -> 2000 | K27: =SUM(K26:K26) -> 2000 | L27: =SUM(L26:L26) -> 2000 | M27: =SUM(M26:M26) -> 2000 | ... U27: =SUM(U26:U26) -> 2000
B28: TOTAL COSTS | F28: =F13+F23+F27 -> 332000 | G28: =G13+G23+G27 -> 330000 | H28: =H13+H23+H27 -> 332000 | I28: =I13+I23+I27 -> 32000 | J28: =J13+J23+J27 -> 192000 | K28: =K13+K23+K27 -> 192000 | L28: =L13+L23+L27 -> 202000 | M28: =M13+M23+M27 -> 192000 | ... U28: =U13+U23+U27 -> 202000
B30: GROSS MARGIN | C30: Kgs/annum | G30: =G8-G13-G23 -> -330000 | H30: =H8-H13-H23 -> -130000 | I30: =I8-I13-I23 -> 170000 | J30: =J8-J13-J23 -> 10000 | K30: =K8-K13-K23 -> 10000 | L30: =L8-L13-L23 -> 0 | M30: =M8-M13-M23 -> 10000 | N30: =N8-N13-N23 -> 10000 | ... U30: =U8-U13-U23 -> 0
B31: NET MARGIN BEFORE PROFIT TAX | C31: kgs/annum | G31: =G30-G27 -> -330000 | H31: =H30-H27 -> -132000 | I31: =I30-I27 -> 168000 | J31: =J30-J27 -> 8000 | K31: =K30-K27 -> 8000 | L31: =L30-L27 -> -2000 | M31: =M30-M27 -> 8000 | N31: =N30-N27 -> 8000 | ... U31: =U30-U27 -> -2000
B32: FIRR | G32: =IRR(H31:U31) -> 0.38269858
B33: FNPV | G33: =NPV(0.1,G31:U31) -> -257382.15
B36: ECONOMIC
C37: Unit | D37: Quantity | E37: Price | F37: Amount | G37: Year
B38: REVENUE | G38: 1 | H38: =G38+1 -> 2 | I38: =H38+1 -> 3 | J38: =I38+1 -> 4 | K38: =J38+1 -> 5 | L38: =K38+1 -> 6 | M38: =L38+1 -> 7 | N38: =M38+1 -> 8 | O38: =N38+1 -> 9 | P38: =O38+1 -> 10 | Q38: 11 | R38: 12 | S38: 13 | T38: 14 | U38: 15
B39: Electricity saved | C39: KWH/h | D39: =D4 -> 80000 | E39: =E4*1.1 -> 2.75 | F39: =F4*0.9 -> 0 | G39: =F39 -> 0 | H39: =J39 -> 180000 | I39: =J39 -> 180000 | J39: =J4*0.9 -> 180000 | K39: =J39 -> 180000 | L39: =K39 -> 180000 | M39: =L39 -> 180000 | N39: =M39 -> 180000 | O39: =N39 -> 180000 | P39: =O39 -> 180000 | Q39: =P39 -> 180000 | R39: =Q39 -> 180000 | ... U39: =T39 -> 180000
B40: Productivity | C40: Lumpsum | D40: 1 | E40: =E5 -> 0 | F40: =F7*0.9 -> 0 | G40: =F40 -> 0 | H40: =J40 -> 0 | I40: =H40 -> 0 | J40: =E40*0.9 -> 0 | K40: =J40 -> 0 | L40: =K40 -> 0 | M40: =L40 -> 0 | N40: =M40 -> 0 | O40: =N40 -> 0 | P40: =O40 -> 0 | Q40: =P40 -> 0 | R40: =Q40 -> 0 | ... U40: =T40 -> 0
J41: =E41*0.9 -> 0 | K41: =F41*0.9 -> 0 | L41: =G41*0.9 -> 0 | M41: =H41*0.9 -> 0 | N41: =I41*0.9 -> 0 | O41: =J41*0.9 -> 0 | P41: =K41*0.9 -> 0 | Q41: =L41*0.9 -> 0 | ... U41: =P41*0.9 -> 0
B42: Sub-total Revenue | D42: =D8 -> 0 | E42: =E8*0.9 -> 0 | F42: =SUM(F39:F41) -> 0 | G42: =SUM(G39:G41) -> 0 | H42: =SUM(H39:H41) -> 180000 | I42: =I8 -> 200000 | J42: =SUM(J39:J41) -> 180000 | K42: =SUM(K39:K41) -> 180000 | L42: =SUM(L39:L41) -> 180000 | M42: =SUM(M39:M41) -> 180000 | N42: =SUM(N39:N41) -> 180000 | O42: =SUM(O39:O41) -> 180000 | P42: =SUM(P39:P41) -> 180000 | Q42: =SUM(Q39:Q41) -> 180000 | ... U42: =SUM(U39:U41) -> 180000
D43: =D9 -> 0 | E43: =E9*0.9 -> 0
B44: CAPEX | D44: =D10 -> 0 | E44: =E10*0.9 -> 0
B45: Investment Costs | D45: =D11 -> 0 | E45: =E11*0.9 -> 0
B46: Fixed Capital, and other equipment | C46: Nos. | D46: 10 | E46: =E12*0.9 -> 27000 | F46: =F12*0.9 -> 270000 | G46: =G12 -> 300000 | I46: 0 | J46: 0 | P46: =K46 -> 0
...

Sheet  financing total
A1: Financial
A2: Net Margins | B2: Particulars | C2: Year 1 | D2: Year 2 | E2: Year 3 | F2: Year 4 | G2: Year 5 | H2: Year 6 | I2: Year 7 | J2: Year 8 | K2: Year 9 | L2: Year 10 | M2: Year 11 | N2: Year 12 | O2: Year 13 | P2: Year 14 | Q2: Year 15
B3: Roof and Ceilling insulation | C3: ='Roof and Ceilling insulation'!G24 -> -919166.67 | D3: ='Roof and Ceilling insulation'!H24 -> 789166.67 | E3: ='Roof and Ceilling insulation'!I24 -> -160833.33 | F3: ='Roof and Ceilling insulation'!J24 -> 160833.33 | G3: ='Roof and Ceilling insulation'!K24 -> 160833.33 | H3: ='Roof and Ceilling insulation'!L24 -> 160833.33 | I3: ='Roof and Ceilling insulation'!M24 -> 160833.33 | J3: ='Roof and Ceilling insulation'!N24 -> 160833.33 | ... Q3: ='Roof and Ceilling insulation'!U24 -> 160833.33
B4: wall insulation | C4: ='Wall insulation'!G31 -> -1208333.3 | D4: ='Wall insulation'!H31 -> 310666.67 | E4: ='Wall insulation'!I31 -> 310666.67 | F4: ='Wall insulation'!J31 -> 310666.67 | G4: ='Wall insulation'!K31 -> 310666.67 | H4: ='Wall insulation'!L31 -> 310666.67 | I4: ='Wall insulation'!M31 -> 310666.67 | J4: ='Wall insulation'!N31 -> 310666.67 | ... Q4: ='Wall insulation'!U31 -> 310666.67
B5: Efficient windows (double tripple glazing) | C5: ='Efficient Windows (Double Tripl'!G28 -> 265600 | D5: ='Efficient Windows (Double Tripl'!H28 -> 265600 | E5: ='Efficient Windows (Double Tripl'!I28 -> 265600 | F5: ='Efficient Windows (Double Tripl'!J28 -> 265600 | G5: ='Efficient Windows (Double Tripl'!K28 -> -544400 | H5: ='Efficient Windows (Double Tripl'!L28 -> -484400 | I5: ='Efficient Windows (Double Tripl'!M28 -> -412400 | J5: ='Efficient Windows (Double Tripl'!N28 -> -326000 | ... Q5: ='Efficient Windows (Double Tripl'!U28 -> 1443120.9
B6: Efficient heating system | C6: ='Efficient heating systems'!G30 -> -289533.33 | D6: ='Efficient heating systems'!H30 -> 113466.67 | E6: ='Efficient heating systems'!I30 -> 113466.67 | F6: ='Efficient heating systems'!J30 -> 113466.67 | G6: ='Efficient heating systems'!K30 -> 113466.67 | H6: ='Efficient heating systems'!L30 -> 113466.67 | I6: ='Efficient heating systems'!M30 -> 113466.67 | J6: ='Efficient heating systems'!N30 -> 113466.67 | ... S6: ='Efficient heating systems'!W30 -> 0
B7: Air sealing/draft proofing | C7: ='Air Sealing Draft Proofing'!G31 -> -330000 | D7: ='Air Sealing Draft Proofing'!H31 -> -132000 | E7: ='Air Sealing Draft Proofing'!I31 -> 168000 | F7: ='Air Sealing Draft Proofing'!J31 -> 8000 | G7: ='Air Sealing Draft Proofing'!K31 -> 8000 | H7: ='Air Sealing Draft Proofing'!L31 -> -2000 | I7: ='Air Sealing Draft Proofing'!M31 -> 8000 | J7: ='Air Sealing Draft Proofing'!N31 -> 8000 | ... Q7: ='Air Sealing Draft Proofing'!U31 -> -2000
B8: Total | C8: =SUM(C3:C7) -> -2481433.3 | D8: =SUM(D3:D7) -> 1346900 | E8: =SUM(E3:E7) -> 696900 | F8: =SUM(F3:F7) -> 858566.67 | G8: =SUM(G3:G7) -> 48566.667 | H8: =SUM(H3:H7) -> 98566.667 | I8: =SUM(I3:I7) -> 180566.67 | J8: =SUM(J3:J7) -> 266966.67 | ... Q8: =SUM(Q3:Q7) -> 2026087.6
B9: Total investment | C9: =Summary!B11 -> 7595000 | T9: Total investment | V9: 11 | W9: Million
B10: Total component cost | C10: =V11 -> 957000000 | U10: US$ | V10: =11000000 -> 11000000
B11: Net margins for the additional financing | C11: =C8*($C$10/$C$9) -> -3.126704e+08 | D11: =D8*($C$10/$C$9) -> 1.6971472e+08 | E11: =E8*($C$10/$C$9) -> 87812153 | F11: =-(F8*($C$10/$C$9)) -> -1.0818279e+08 | G11: =G8*($C$10/$C$9) -> 6119591.8 | H11: =H8*($C$10/$C$9) -> 12419789 | I11: =I8*($C$10/$C$9) -> 22752113 | J11: =J8*($C$10/$C$9) -> 33638855 | K11: =K8*($C$10/$C$9) -> 45442905 | L11: =L8*($C$10/$C$9) -> 62379851 | M11: =M8*($C$10/$C$9) -> 81192140 | N11: =N8*($C$10/$C$9) -> 1.0250685e+08 | ... Q11: =Q8*($C$10/$C$9) -> 2.5529504e+08 | U11: kgs$ | V11: 957000000
B12: FIRR | C12: =IRR(C11:Q11) -> 0.15352652
B13: FNPV | C13: =NPV(0.1,C11:Q11) -> 1.0289503e+08
C16: =V11 -> 957000000
C20: =NPV(0.1,C18:Q18) -> 0
A23: Economic
A24: Net Margins | B24: Particulars | C24: Year 1 | D24: Year 2 | E24: Year 3 | F24: Year 4 | G24: Year 5 | H24: Year 6 | I24: Year 7 | J24: Year 8 | K24: Year 9 | L24: Year 10 | M24: Year 11 | N24: Year 12 | O24: Year 13 | P24: Year 14 | Q24: Year 15
B25: Roof and Ceilling insulation | C25: ='Roof and Ceilling insulation'!G57 -> -601999 | D25: ='Roof and Ceilling insulation'!H57 -> -287252 | E25: ='Roof and Ceilling insulation'!I57 -> -287253 | F25: ='Roof and Ceilling insulation'!J57 -> 287254 | G25: ='Roof and Ceilling insulation'!K57 -> 287255 | H25: ='Roof and Ceilling insulation'!L57 -> 287256 | I25: ='Roof and Ceilling insulation'!M57 -> 287257 | J25: ='Roof and Ceilling insulation'!N57 -> 287258 | ... Q25: ='Roof and Ceilling insulation'!U57 -> 207250
B26: wall insulation | C26: ='Wall insulation'!G70 -> -842500 | D26: ='Wall insulation'!H70 -> -316600 | E26: ='Wall insulation'!I70 -> 316600 | F26: ='Wall insulation'!J70 -> 316600 | G26: ='Wall insulation'!K70 -> 316600 | H26: ='Wall insulation'!L70 -> 316600 | I26: ='Wall insulation'!M70 -> 316600 | J26: ='Wall insulation'!N70 -> 316600 | ... Q26: ='Wall insulation'!U70 -> 316600
B27: Efficient windows (double tripple glazing) | C27: ='Efficient Windows (Double Tripl'!G68 -> 1866340 | D27: ='Efficient Windows (Double Tripl'!H68 -> 1866340 | E27: ='Efficient Windows (Double Tripl'!I68 -> 1866340 | F27: ='Efficient Windows (Double Tripl'!J68 -> -1866340 | G27: ='Efficient Windows (Double Tripl'!K68 -> 1866340 | H27: ='Efficient Windows (Double Tripl'!L68 -> -1866340 | I27: ='Efficient Windows (Double Tripl'!M68 -> -1866340 | J27: ='Efficient Windows (Double Tripl'!N68 -> -1866340 | ... Q27: ='Efficient Windows (Double Tripl'!U68 -> -1866340
B28: Efficient heating system | C28: ='Efficient heating systems'!G63 -> -227200 | D28: ='Efficient heating systems'!H63 -> -122000 | E28: ='Efficient heating systems'!I63 -> -122000 | F28: ='Efficient heating systems'!J63 -> 122000 | G28: ='Efficient heating systems'!K63 -> 122000 | H28: ='Efficient heating systems'!L63 -> 122000 | I28: ='Efficient heating systems'!M63 -> 122000 | J28: ='Efficient heating systems'!N63 -> 122000 | ... Q28: ='Efficient heating systems'!U63 -> 122000
B29: Air sealing/draft proofing | C29: ='Air Sealing Draft Proofing'!G65 -> -328800 | D29: ='Air Sealing Draft Proofing'!H65 -> 153000 | E29: ='Air Sealing Draft Proofing'!I65 -> 171200 | F29: ='Air Sealing Draft Proofing'!J65 -> 43200 | G29: ='Air Sealing Draft Proofing'!K65 -> 43200 | H29: ='Air Sealing Draft Proofing'!L65 -> 43200 | I29: ='Air Sealing Draft Proofing'!M65 -> 43200 | J29: ='Air Sealing Draft Proofing'!N65 -> 43200 | ... Q29: ='Air Sealing Draft Proofing'!U65 -> 33200
B30: Total | C30: =SUM(C25:C29) -> -134159 | D30: =SUM(D25:D29) -> 1293488 | E30: =SUM(E25:E29) -> 1944887 | F30: =SUM(F25:F29) -> -1097286 | G30: =SUM(G25:G29) -> 2635395 | H30: =SUM(H25:H29) -> -1097284 | I30: =SUM(I25:I29) -> -1097283 | J30: =SUM(J25:J29) -> -1097282 | ... Q30: =SUM(Q25:Q29) -> -1187290
B31: Total investment | C31: =C9 -> 7595000
B32: Total component cost | C32: =C10 -> 957000000
B33: Net margins for additional financing | C33: =-(C30*($C$10/$C$9)) -> 16904564 | D33: =(D30*($C$10/$C$9)) -> 1.629846e+08 | E33: =E30*($C$10/$C$9) -> 2.4506344e+08 | F33: =F30*($C$10/$C$9) -> -1.3826237e+08 | G33: =(G30*($C$10/$C$9)) -> 3.3207018e+08 | H33: =H30*($C$10/$C$9) -> -1.3826212e+08 | I33: =I30*($C$10/$C$9) -> -1.3826199e+08 | J33: =J30*($C$10/$C$9) -> -1.3826187e+08 | K33: =K30*($C$10/$C$9) -> -1.3826174e+08 | L33: =L30*($C$10/$C$9) -> -1.3826161e+08 | M33: =M30*($C$10/$C$9) -> -1.4834319e+08 | N33: =N30*($C$10/$C$9) -> -1.4960323e+08 | O33: =O30*($C$10/$C$9) -> -1.4834319e+08 | ... Q33: =Q30*($C$10/$C$9) -> -1.4960323e+08
B34: EIRR | C34: =IRR(C33:Q33) -> 0.13446542
B35: ENPV | C35: =NPV(0.1,C33:Q33)*(-1) -> 97006673
C45: =NPV(0.1,C43:Q43) -> 0

Sheet Sensitivity analysis
A1: Financial
A2: Net Margins | B2: Particulars | C2: Year 1 | D2: Year 2 | E2: Year 3 | F2: Year 4 | G2: Year 5 | H2: Year 6 | I2: Year 7 | J2: Year 8 | K2: Year 9 | L2: Year 10 | M2: Year 11 | N2: Year 12 | O2: Year 13 | P2: Year 14 | Q2: Year 15
B3: Total investment | C3: =Summary!B11 -> 7595000 | T3: Total investment | V3: 10 | W3: Million
B4: Total component cost | C4: =V6 -> 2299000000 | U4: US$ | V4: =10000000 -> 10000000
B5: NET margins | C5: =' financing total'!C11 -> -3.126704e+08 | D5: =' financing total'!D11 -> 1.6971472e+08 | E5: =' financing total'!E11 -> 87812153 | F5: =' financing total'!F11 -> -1.0818279e+08 | G5: =' financing total'!G11 -> 6119591.8 | H5: =' financing total'!H11 -> 12419789 | I5: =' financing total'!I11 -> 22752113 | J5: =' financing total'!J11 -> 33638855 | ... Q5: =' financing total'!Q11 -> 2.5529504e+08
U6: G$ | V6: 2299000000
C8: =NPV(0.1,C6:Q6) -> 0
C11: =V6 -> 2299000000
B12: Net Margins | C12: =C5 -> -3.126704e+08 | D12: =(D5) -> 1.6971472e+08 | E12: =(E5) -> 87812153 | F12: =(F5) -> -1.0818279e+08 | G12: =(G5) -> 6119591.8 | H12: =(H5) -> 12419789 | I12: =(I5) -> 22752113 | J12: =(J5) -> 33638855 | K12: =(K5) -> 45442905 | ... Q12: =(Q5) -> 2.5529504e+08
B13: FIRR | C13: =IRR(C12:Q12) -> 0.15352652
B14: FNPV | C14: =' financing total'!C13 -> 1.0289503e+08
B16: Net Margins (10% reduced revenue) | C16: =C12 -> -3.126704e+08 | D16: =D12*0.9 -> 1.5274325e+08 | E16: =E12*0.9 -> 79030937 | F16: =F12*0.9 -> -97364512 | G16: =G12*0.9 -> 5507632.7 | H16: =H12*0.9 -> 11177810 | I16: =I12*0.9 -> 20476902 | J16: =J12*0.9 -> 30274969 | K16: =K12*0.9 -> 40898614 | ... Q16: =Q12*0.9 -> 2.2976554e+08
B17: FNPV(10% reduced revenue) | C17: =NPV(0.1,C16:Q16) -> 64180949
B18: FIRR (10% reduced revenue) | C18: =IRR(C16:Q16) -> 0.13370172
B21: Net Margins (2 years delayed return) | C21: =C12 -> -3.126704e+08 | F21: =-(F12) -> 1.0818279e+08 | G21: =G12 -> 6119591.8 | H21: =H12 -> 12419789 | I21: =I12 -> 22752113 | J21: =J12 -> 33638855 | K21: =K12 -> 45442905 | L21: =L12 -> 62379851 | M21: =M12 -> 81192140 | N21: =N12 -> 1.0250685e+08 | ... Q21: =Q12 -> 2.5529504e+08
B23: FNPV(2 years delayed return) | C23: =NPV(0.1,C21:Q21) -> 1.134652e+08
B25: FIRR(2 years delayed return) | C25: =IRR(C21:Q21) -> 0.1578973
B27: Net Margins (10% increase cost) | C27: =C12*1.1 -> -3.4393744e+08 | D27: =D12 -> 1.6971472e+08 | E27: =E12 -> 87812153 | F27: =F12*1.1 -> -1.1900107e+08 | G27: =G12*1.1 -> 6731551 | H27: =H12*1.1 -> 13661768 | I27: =I12*1.1 -> 25027325 | J27: =J12*1.1 -> 37002740 | K27: =K12*1.1 -> 49987195 | L27: =L12*1.1 -> 68617837 | M27: =M12*1.1 -> 89311354 | ... Q27: =Q12*1.1 -> 2.8082454e+08
B29: FIRR(10% increase cost) | C29: 0.2
B30: Fnpv (10% reduced cost) | C30: =NPV(0.1,C27:Q27) -> 92561071
A31: Economic
A32: Net Margins | B32: Particulars | C32: Year 1 | D32: Year 2 | E32: Year 3 | F32: Year 4 | G32: Year 5 | H32: Year 6 | I32: Year 7 | J32: Year 8 | K32: Year 9 | L32: Year 10 | M32: Year 11 | N32: Year 12 | O32: Year 13 | P32: Year 14 | Q32: Year 15
B33: Total investment | C33: =C3 -> 7595000
B34: Total component cost | C34: =C4 -> 2299000000
B36: Net margins | C36: =' financing total'!C33 -> 16904564 | D36: =' financing total'!D33 -> 1.629846e+08 | E36: =' financing total'!E33 -> 2.4506344e+08 | F36: =' financing total'!F33 -> -1.3826237e+08 | G36: =' financing total'!G33 -> 3.3207018e+08 | H36: =' financing total'!H33 -> -1.3826212e+08 | I36: =' financing total'!I33 -> -1.3826199e+08 | J36: =' financing total'!J33 -> -1.3826187e+08 | ... Q36: =' financing total'!Q33 -> -1.4960323e+08
C39: =NPV(0.1,C35:Q35) -> 0
B42: EIRR | C42: =' financing total'!C34 -> 0.13446542
B43: ENPV | C43: =' financing total'!C35 -> 97006673
B46: Net Margins (10% reduced revenue) | C46: =C36*0.9 -> 15214108 | D46: =D36*0.9 -> 1.4668614e+08 | E46: =E36*0.9 -> 2.205571e+08 | F46: =F36*0.9 -> -1.2443613e+08 | G46: =G36*0.9 -> 2.9886316e+08 | H46: =H36*0.9 -> -1.2443591e+08 | I46: =I36*0.9 -> -1.2443579e+08 | J46: =J36*0.9 -> -1.2443568e+08 | ... Q46: =Q36*0.9 -> -1.3464291e+08
B47: FNPV(10% reduced revenue) | C47: =-(NPV(0.1,C46:Q46)) -> 87306005
B48: FIRR (10% reduced revenue) | C48: =IRR(C46:Q46) -> 0.13446542
B51: Net Margins (2 years delayed return) | C51: =C36 -> 16904564 | F51: =F37 -> 0 | G51: =G37 -> 0 | H51: =H37 -> 0 | I51: =I37 -> 0 | J51: =J37 -> 0 | K51: =K37 -> 0 | L51: =L37 -> 0 | M51: =M37 -> 0 | ... Q51: =Q37 -> 0
B53: FNPV(2 years delayed return) | C53: =NPV(0.1,C51:Q51) -> 15367785
B55: FIRR(2 years delayed return)
B57: Net Margins (10% increase cost) | C57: =C36*1.1 -> 18595020 | D57: =D37 -> 0 | E57: =E37 -> 0 | F57: =F37 -> 0 | G57: =G37 -> 0 | H57: =H37 -> 0 | I57: =I37 -> 0 | J57: Scenario2 | K57: FNPV (USD)3 | L57: ENPV (USD)4 | M57: =P37 -> 0 | N57: =Q37 -> 0
J58: Baseline | K58: US$1.18 million | L58: US$1.11 million
B59: FIRR(10% increase cost) | C59: 0.2 | J59: 10% Decrease in Revenue | K59: US$0.74 million | L59: US$1.00 million
B60: Fnpv (10% reduced cost) | C60: =NPV(0.1,C57:N57) -> 16904564 | J60: 10% Increase in Cost | K60: US$1.06 million | L60: US$0.18 million
J61: 2-Year Delayed Return | K61: US$1.30 million | L61: US$0.19 million
C63: topic | D63: EIRR | E63: FIRR | F63: FNPV | G63: ENPV
...

Sheet Efficient buildings
